Workbook

Sheet FINAL
A1: NO. IMP. / EXP. (NOMBRE) | B1: REF.A.A. | C1: PATENTE | D1: PEDIMENTO | E1: PEDIMENTO ORIG. (RECT.) | F1: T.O | G1: CLAVE PEDIMENTO | H1: Tasa Partida IVA | I1: Importe Partida IVA | J1: Tasa Partida CC | K1: Importe Partida CC | L1: Tasa Partida IEPS | M1: Importe Partida IEPS | N1: Tasa Partida IGI/IGE | O1: Importe Partida IGI/IGE | P1: TIPO CAMBIO | Q1: PESO BRUTO | R1: ADUANA DESPACHO | S1: NO. DE CONTENEDOR | T1: BULTOS ARRIBO | U1: Valor Comercial MXP | V1: TOTAL VALOR ADUANA | W1: Seguros | X1: Fletes | Y1: EMBALAJES | Z1: OTROS INC. | AA1: MERCANCÍA (PED.) | AB1: EJE UNIDAD DE NEGOCIO | AC1: VALOR ADUANA (P. PART.) | AD1: PRECIO UNITARIO | AE1: Tasas P/Pedimento | AF1: TASAS P/PARTIDA | AG1: IGI / IGE | AH1: REC | AI1: IVA PREV | AJ1: DTA | AK1: Importe DTA FP2 | AL1: IVA | AM1: PREV | AN1: IMPUESTOS | AO1: Cuenta Origen | AP1: PROVEEDOR / COMPRADOR | AQ1: NO(S) FACTURA(S) | AR1: INCOTERM | AS1: MONEDA | AT1: NO. GUÍA (MASTER) | AU1: NO. GUÍA HOUSE | AV1: Temperatura | AW1: FRACCION(ES) | AX1: NICO | AY1: Cantidad Factura | AZ1: UMC (CANTIDAD) | BA1: Descripcion UMC | BB1: CÓDIGO PRODUCTO | BC1: PAIS O/D | BD1: PAIS V/C | BE1: Resultado Selección | BF1: MOTIVO RETRASO / OTROS | BG1: NO. PERMISOS POR PARTIDA | BH1: PERMISOS POR PARTIDA | BI1: OBSERVACIONES ARRIBO | BJ1: ObservacionesPedimento | BK1: NO. DE COVE | BL1: FOLIO | BM1: 073 ALMACENAJE, MANEJO Y CUSTODIA (P.P.) | BN1: 110 MANIOBRAS (P.P.) | BO1: 077 DESCONSOLIDACION (P.P.) | BP1: 106 SERVICIO EXTRAORDIONARIO (P.P.) | BQ1: 033 CUENTA AMERICANA (P.P.) | BR1: 133 RECONOCIMIENTO ADUANERO (P.P.) | BS1: 034 MONTACARGAS (P.P.) | BT1: 008 HIELO SECO (P.P.) | BU1: 117 TRAMITE SAGARPA (P.P.) | BV1: 012 PAGO DE DERECHOS (P.P.) | BW1: 087 OTROS GASTOS (P.P.) | BX1: 136 SERVICIO DE CUSTODIA (P.P.) | BY1: OTROS GASTOS | BZ1: DESCARGAS | CA1: DEMORAS | CB1: HONORARIOS | CC1: I.V.A. | CD1: SALDO | CE1: EstatusCuentaGastos | CF1: Monto Cuenta de Gastos | CG1: Anticipos o Pagos Registrados | CH1: Saldo2 | CI1: Ejecutivo | CJ1: Ejecutivo_ABC | CK1: Aduana/Sección Despacho | CL1: MES | CM1: FECHA ENTRADA2 | CN1: FECHA PAGO2 | CO1: Entrada de pago | CP1: Etiqueta Entrada a Pago | CQ1: FECHA DE CRUCE2 | CR1: Entrada a Cruce | CS1: Entrada a cruce excel | CT1: ETIQUETA ENTRADA A CRUCE excel | CU1: KPI ENTRADA A CRUCE | CV1: Etiqueta entrada a Cruce2 | CW1: FECHA ENTREGA DE MERCANCIA | CX1: Entrada a entrega excel | CY1: ETIQUETA ENTRADA A ENTREGA excel | CZ1: KPI DE ENTRADA A ENTREGA | DA1: Entrada a Entrega | DB1: Etiqueta Entrada a Entrega | DC1: Entrada a Factura | DD1: Etiqueta Entrada a Factura | DE1: Pago Pedimento a Cruce | DF1: Etiqueta Pago Pedimento a Cruce | DG1: Pago a Cruce | DH1: CRUCE A ENTREGA | DI1: ETIQUETA CRUCE A ENTREGA | DJ1: FECHA DE FACTURACIÓN | DK1: ENTREGA A ENTREGA DE FACTURA | DL1: ENTREGA A FACTURA | DM1: FECHA RECIBE FACT | DN1: FECHA TIMBRADO | DO1: TIEMPO DE FACTURACION | DP1: ETIQUETA ENTREGA A FACTURA | DQ1: CuentaG_FechaFactura | DR1: Entrega de mercancia a factura excel | DS1: ETIQUETA ENTREGA A FACTURA excel | DT1: KPI entrega a factura | DU1: VERIFICADOR | DV1: Comparacion | DW1: Clave Pedimento2 | DX1: Ejecutivo_ABC3 | DY1: Guia Master | DZ1: Guia House | EA1: Pedimento4 | EB1: Tipo Operación Desc | EC1: Mercancía | ED1: TIPO MERCANCIA OK | EE1: CLASIFICACIÓN DE MERCANCIA | EF1: TIPO DE MERCANCIA | EG1: Cliente | EH1: Unidad de negocio | EI1: MOTIVO DE RETRASO | EJ1: MOTIVO DE RETRASO OTRO | EK1: MOTIVO DE RETRASO COMPLETO | EL1: Ejecutivo_Tipo_Mercancia | EM1: Primera Selección | EN1: TRANSPORTISTA. | EO1: UNIDAD RENTADA | EP1: UNIDAD SUPER EXPRESS | EQ1: RFC_Importador | ER1: OtrosIncPed | ES1: Nico5 | ET1: Mercancia_CovesSubModelo | EU1: Días Credito | EV1: Valor Moneda Factura | EW1: UMT DESCRIPCION | EX1: Motivo de Rectificación | EY1: Nombre País Origen/Destino | EZ1: Nombre País Vendedor/Comprador | FA1: Clave de País Origen/Destino | FB1: Clave de País Vendedor/Comprador | FC1: Aduana/Sección Despacho2 | FD1: Fecha de Pago3 | FE1: MES4 | FF1: Fecha Entrada/Presentación5 | FG1: Fecha de Pago funcion6 | FH1: Entrada de pago7 | FI1: Etiqueta Entrada a Pago8 | FJ1: Fecha primera Selección9 | FK1: Entrada a Cruce10 | FL1: Etiqueta entrada a Cruce | FM1: Pago Pedimento a Cruce11 | FN1: Etiqueta Pago Pedimento a Cruce12 | FO1: Pago a Cruce13 | FP1: CRUCE A ENTREGA14 | FQ1: ETIQUETA CRUCE A ENTREGA15 | FR1: FECHA ENTREGA DE MERCANCIA16 | FS1: Entrada a Entrega17 | FT1: Etiqueta Entrada a Entrega18 | FU1: Entrada a Factura19 | FV1: Etiqueta Entrada a Factura20 | FW1: FECHA DE FACTURACIÓN21 | FX1: ENTREGA A ENTREGA DE FACTURA 22 | FY1: ENTREGA A FACTURA23 | FZ1: FECHA RECIBE FACT24 | GA1: FECHA TIMBRADO25 | GB1: CuentaG_FechaFactura26 | GC1: TIEMPO DE FACTURACION27 | GD1: CuentaG_FechaFactura2 | GE1: ETIQUETA ENTREGA A FACTURA28 | GF1: CuentaG_FechaFactura3 | GG1: VERIFICADOR29 | GH1: Comparacion30 | GI1: Clave Pedimento31 | GJ1: Ejecutivo_ABC32 | GK1: Guia Master33 | GL1: Guia House34 | GM1: Pedimento35 | GN1: Tipo Operación Desc36 | GO1: Mercancía37 | GP1: TIPO MERCANCIA OK38 | GQ1: CLASIFICACIÓN DE MERCANCIA39 | GR1: TIPO DE MERCANCIA40 | GS1: Cliente41 | GT1: Unidad de negocio42 | GU1: MOTIVO DE RETRASO43 | GV1: MOTIVO DE RETRASO OTRO44 | GW1: MOTIVO DE RETRASO COMPLETO45 | GX1: Ejecutivo_Tipo_Mercancia46 | GY1: Primera Selección47 | GZ1: TRANSPORTISTA.48 | HA1: UNIDAD RENTADA49 | HB1: UNIDAD SUPER EXPRESS50 | HC1: RFC_Importador51 | HD1: OtrosIncPed52 | HE1: Nico53 | HF1: Mercancia_CovesSubModelo54 | HG1: Días Credito55 | HH1: Valor Moneda Factura 56 | HI1: UMT DESCRIPCION57 | HJ1: Motivo de Rectificación58 | HK1: Nombre País Origen/Destino59 | HL1: Nombre País Vendedor/Comprador60 | HM1: Clave de País Origen/Destino61 | HN1: Clave de País Vendedor/Comprador62 | HO1: Valor Aduana | HP1: Importe DTA FP1 | HQ1: Importe IVA 1 | HR1: IGI | HS1: TotalCuentadeGastos | HT1: Sucursal | HU1: Tipo Sucursal
A2: INTERVET MEXICO SA DE CV | B2: 26-001222 | C2: 3942 | D2: 6001223 | F2: Importación | G2: A1 | H2: 16 | I2: 93586 | J2: 0 | K2: 0 | L2: 0 | M2: 0 | N2: 0 | O2: 0 | P2: 17.17 | Q2: 122 | R2: 470 | T2: 1 BULTOS | U2: 586895 | V2: 586895 | W2: 0 | X2: 0 | Y2: 0 | Z2: 0 | AA2: ESTACION BASE (CONTROLLER SENSEHUB US) | AC2: 580268 | AD2: 13815.905 | AE2: 354 | AF2: 16.00, 16.00 | AG2: 0 | AH2: 0 | AI2: 53 | AJ2: 4695 | AK2: 0 | AL2: 94655 | AM2: 330 | AN2: 99733 | AO2: Cliente | AP2: INTERVET INTERNATIONAL B.V. | AQ2: 210367184 | AR2: CIP | AS2: MXP | AT2: 057-02191140 | AV2: SECO | AW2: 85176101 | AX2: 0 | AY2: 42 | AZ2: 42 | BA2: PIEZA | BC2: ISR | BD2: ZYA | BE2: DESADUANAMIENTO LIBRE | BJ2: PROCEDENCIA: ISRAEL FACTURA C | BK2: COVE267ZLBAN6 | BL2: 44228 | BM2: 0 | BN2: 0 | BO2: 0 | BP2: 0 | BQ2: 0 | BR2: 0 | BS2: 0 | BT2: 0 | BU2: 0 | BV2: 0 | BW2: 0 | BX2: 0 | BY2: 0 | BZ2: 0 | CA2: 0 | CB2: 5300 | CC2: 952 | CD2: 20944.87 | CE2: PEDIENTE DE PAGO | CF2: 20944.87 | CG2: 0 | CH2: 0 | CI2: DANIEL ULISES MORALES REYES | CJ2: KAREN MARTINEZ | CK2: =_xlfn.XLOOKUP($B$2,'BASE DE EXCEL'!C:C,'BASE DE EXCEL'!D:D,"NO HAY REFERENCIA") -> 470 | CL2: =_xlfn.XLOOKUP($B$2,'BASE DE EXCEL'!$C:$C,'BASE DE EXCEL'!F:F,"NO HAY REFERENCIA") -> 3 | CM2: =_xlfn.XLOOKUP($B$2,'BASE DE EXCEL'!$C:$C,'BASE DE EXCEL'!G:G,"NO HAY REFERENCIA") -> 46080 | CN2: =_xlfn.XLOOKUP($B$2,'BASE DE EXCEL'!$C:$C,'BASE DE EXCEL'!H:H,"NO HAY REFERENCIA") -> 46086 | CO2: =_xlfn.XLOOKUP($B$2,'BASE DE EXCEL'!$C:$C,'BASE DE EXCEL'!I:I,"NO HAY REFERENCIA") -> 4 | CP2: =_xlfn.XLOOKUP($B$2,'BASE DE EXCEL'!$C:$C,'BASE DE EXCEL'!J:J,"NO HAY REFERENCIA") -> 4 a 5 días | CQ2: =_xlfn.XLOOKUP($B$2,'BASE DE EXCEL'!$C:$C,'BASE DE EXCEL'!K:K,"NO HAY REFERENCIA") -> 46087 | CR2: =_xlfn.XLOOKUP($B$2,'BASE DE EXCEL'!$C:$C,'BASE DE EXCEL'!L:L,"NO HAY REFERENCIA") -> 5 | CS2: =_xlfn.XLOOKUP($B$2,'BASE DE EXCEL'!$C:$C,'BASE DE EXCEL'!M:M,"NO HAY REFERENCIA") -> 6 | CT2: =_xlfn.XLOOKUP($B$2,'BASE DE EXCEL'!$C:$C,'BASE DE EXCEL'!N:N,"NO HAY REFERENCIA") -> 6 a 10 días | CU2: =_xlfn.XLOOKUP($B$2,'BASE DE EXCEL'!$C:$C,'BASE DE EXCEL'!O:O,"NO HAY REFERENCIA") -> On Time | CV2: =_xlfn.XLOOKUP(B2,'BASE DE EXCEL'!$C:$C,'BASE DE EXCEL'!P:P,"NO HAY REFERENCIA") -> 6 a 10 días | CW2: =_xlfn.XLOOKUP(B2,'BASE DE EXCEL'!$C:$C,'BASE DE EXCEL'!Q:Q,"NO HAY REFERENCIA") -> 46087 | CX2: =_xlfn.XLOOKUP(B2,'BASE DE EXCEL'!$C:$C,'BASE DE EXCEL'!R:R,"NO HAY REFERENCIA") -> 6 | CY2: =_xlfn.XLOOKUP(B2,'BASE DE EXCEL'!$C:$C,'BASE DE EXCEL'!S:S,"NO HAY REFERENCIA") -> 6 a 10 días | CZ2: =_xlfn.XLOOKUP(B2,'BASE DE EXCEL'!$C:$C,'BASE DE EXCEL'!T:T,"NO HAY REFERENCIA") -> On Time | DA2: =_xlfn.XLOOKUP(B2,'BASE DE EXCEL'!$C:$C,'BASE DE EXCEL'!U:U,"NO HAY REFERENCIA") -> 7 | DB2: =_xlfn.XLOOKUP(B2,'BASE DE EXCEL'!$C:$C,'BASE DE EXCEL'!V:V,"NO HAY REFERENCIA") -> 4 a 5 días | DC2: =_xlfn.XLOOKUP(B2,'BASE DE EXCEL'!$C:$C,'BASE DE EXCEL'!W:W,"NO HAY REFERENCIA") -> NULL | DD2: =_xlfn.XLOOKUP(B2,'BASE DE EXCEL'!$C:$C,'BASE DE EXCEL'!X:X,"NO HAY REFERENCIA") -> SIN DATO | DE2: =_xlfn.XLOOKUP(B2,'BASE DE EXCEL'!$C:$C,'BASE DE EXCEL'!Y:Y,"NO HAY REFERENCIA") -> 1 | DF2: =_xlfn.XLOOKUP(B2,'BASE DE EXCEL'!$C:$C,'BASE DE EXCEL'!Z:Z,"NO HAY REFERENCIA") -> 1 día o menos | DG2: =_xlfn.XLOOKUP(B2,'BASE DE EXCEL'!$C:$C,'BASE DE EXCEL'!AA:AA,"NO HAY REFERENCIA") -> 6 | DH2: =_xlfn.XLOOKUP(B2,'BASE DE EXCEL'!$C:$C,'BASE DE EXCEL'!AB:AB,"NO HAY REFERENCIA") -> 0 | DI2: =_xlfn.XLOOKUP(B2,'BASE DE EXCEL'!$C:$C,'BASE DE EXCEL'!AC:AC,"NO HAY REFERENCIA") -> 1 día o menos | DJ2: =_xlfn.XLOOKUP(B2,'BASE DE EXCEL'!$C:$C,'BASE DE EXCEL'!AD:AD,"NO HAY REFERENCIA") -> 46113 | DK2: =_xlfn.XLOOKUP(B2,'BASE DE EXCEL'!$C:$C,'BASE DE EXCEL'!AE:AE,"NO HAY REFERENCIA") -> 5 | DL2: =_xlfn.XLOOKUP(B2,'BASE DE EXCEL'!$C:$C,'BASE DE EXCEL'!AF:AF,"NO HAY REFERENCIA") -> 18 | DM2: =_xlfn.XLOOKUP(B2,'BASE DE EXCEL'!$C:$C,'BASE DE EXCEL'!AG:AG,"NO HAY REFERENCIA") -> 46092 | DN2: =_xlfn.XLOOKUP(B2,'BASE DE EXCEL'!$C:$C,'BASE DE EXCEL'!AH:AH,"NO HAY REFERENCIA") -> 46093 | DO2: =_xlfn.XLOOKUP(B2,'BASE DE EXCEL'!$C:$C,'BASE DE EXCEL'!AI:AI,"NO HAY REFERENCIA") -> NULL | DP2: =_xlfn.XLOOKUP(B2,'BASE DE EXCEL'!$C:$C,'BASE DE EXCEL'!AJ:AJ,"NO HAY REFERENCIA") -> más de 16 días | DQ2: =_xlfn.XLOOKUP(B2,'BASE DE EXCEL'!$C:$C,'BASE DE EXCEL'!AK:AK,"NO HAY REFERENCIA") -> 46113 | DR2: =_xlfn.XLOOKUP(B2,'BASE DE EXCEL'!$C:$C,'BASE DE EXCEL'!AL:AL,"NO HAY REFERENCIA") -> 18 | DS2: =_xlfn.XLOOKUP(B2,'BASE DE EXCEL'!$C:$C,'BASE DE EXCEL'!AM:AM,"NO HAY REFERENCIA") -> más de 16 días | DT2: =_xlfn.XLOOKUP(B2,'BASE DE EXCEL'!$C:$C,'BASE DE EXCEL'!AN:AN,"NO HAY REFERENCIA") -> On Time | DU2: =_xlfn.XLOOKUP(B2,'BASE DE EXCEL'!$C:$C,'BASE DE EXCEL'!AO:AO,"NO HAY REFERENCIA") -> 1 | DV2: =_xlfn.XLOOKUP(B2,'BASE DE EXCEL'!$C:$C,'BASE DE EXCEL'!AP:AP,"NO HAY REFERENCIA") -> Es anterior | DW2: =_xlfn.XLOOKUP(B2,'BASE DE EXCEL'!$C:$C,'BASE DE EXCEL'!AQ:AQ,"NO HAY REFERENCIA") -> A1 | DX2: =_xlfn.XLOOKUP(B2,'BASE DE EXCEL'!$C:$C,'BASE DE EXCEL'!AR:AR,"NO HAY REFERENCIA") -> KAREN MARTINEZ | DY2: =_xlfn.XLOOKUP(B2,'BASE DE EXCEL'!$C:$C,'BASE DE EXCEL'!AS:AS,"NO HAY REFERENCIA") -> 057-02191140 | DZ2: =_xlfn.XLOOKUP(B2,'BASE DE EXCEL'!$C:$C,'BASE DE EXCEL'!AT:AT,"NO HAY REFERENCIA") -> NULL | EA2: =_xlfn.XLOOKUP(B2,'BASE DE EXCEL'!$C:$C,'BASE DE EXCEL'!AU:AU,"NO HAY REFERENCIA") -> 6001223 | EB2: =_xlfn.XLOOKUP(B2,'BASE DE EXCEL'!$C:$C,'BASE DE EXCEL'!AV:AV,"NO HAY REFERENCIA") -> Importación | EC2: =_xlfn.XLOOKUP(B2,'BASE DE EXCEL'!$C:$C,'BASE DE EXCEL'!AW:AW,"NO HAY REFERENCIA") -> ESTACION BASE (CONTROLLER SENSEHUB US) | ED2: =_xlfn.XLOOKUP(B2,'BASE DE EXCEL'!$C:$C,'BASE DE EXCEL'!AX:AX,"NO HAY REFERENCIA") -> SIN CLASIFICACION | EE2: =_xlfn.XLOOKUP(B2,'BASE DE EXCEL'!$C:$C,'BASE DE EXCEL'!AY:AY,"NO HAY REFERENCIA") -> 0 | EF2: =_xlfn.XLOOKUP(B2,'BASE DE EXCEL'!$C:$C,'BASE DE EXCEL'!AZ:AZ,"NO HAY REFERENCIA") -> Cargas de Importación | EG2: =_xlfn.XLOOKUP(B2,'BASE DE EXCEL'!$C:$C,'BASE DE EXCEL'!BA:BA,"NO HAY REFERENCIA") -> INTERVET MEXICO SA DE CV | EH2: =_xlfn.XLOOKUP(B2,'BASE DE EXCEL'!$C:$C,'BASE DE EXCEL'!BB:BB,"NO HAY REFERENCIA") -> 0 | EI2: =_xlfn.XLOOKUP(B2,'BASE DE EXCEL'!$C:$C,'BASE DE EXCEL'!BC:BC,"NO HAY REFERENCIA") -> 0 | EJ2: =_xlfn.XLOOKUP(B2,'BASE DE EXCEL'!$C:$C,'BASE DE EXCEL'!BD:BD,"NO HAY REFERENCIA") -> 0 | EK2: =_xlfn.XLOOKUP(B2,'BASE DE EXCEL'!$C:$C,'BASE DE EXCEL'!BE:BE,"NO HAY REFERENCIA") -> 0 | EL2: =_xlfn.XLOOKUP(B2,'BASE DE EXCEL'!$C:$C,'BASE DE EXCEL'!BF:BF,"NO HAY REFERENCIA") -> REFACCIONES | EM2: =_xlfn.XLOOKUP(B2,'BASE DE EXCEL'!$C:$C,'BASE DE EXCEL'!BG:BG,"NO HAY REFERENCIA") -> Verde | EN2: =_xlfn.XLOOKUP(B2,'BASE DE EXCEL'!$C:$C,'BASE DE EXCEL'!BH:BH,"NO HAY REFERENCIA") -> NULL | EO2: =_xlfn.XLOOKUP(B2,'BASE DE EXCEL'!$C:$C,'BASE DE EXCEL'!BI:BI,"NO HAY REFERENCIA") -> 0 | EP2: =_xlfn.XLOOKUP(B2,'BASE DE EXCEL'!$C:$C,'BASE DE EXCEL'!BJ:BJ,"NO HAY REFERENCIA") -> NISSAN 3 | EQ2: =_xlfn.XLOOKUP(B2,'BASE DE EXCEL'!$C:$C,'BASE DE EXCEL'!BK:BK,"NO HAY REFERENCIA") -> IME850329RH2 | ER2: =_xlfn.XLOOKUP(B2,'BASE DE EXCEL'!$C:$C,'BASE DE EXCEL'!BL:BL,"NO HAY REFERENCIA") -> 0 | ES2: =_xlfn.XLOOKUP(B2,'BASE DE EXCEL'!$C:$C,'BASE DE EXCEL'!BM:BM,"NO HAY REFERENCIA") -> 0 | ET2: =_xlfn.XLOOKUP(B2,'BASE DE EXCEL'!$C:$C,'BASE DE EXCEL'!BN:BN,"NO HAY REFERENCIA") -> LOTE: IL20260101 | EU2: =_xlfn.XLOOKUP(B2,'BASE DE EXCEL'!$C:$C,'BASE DE EXCEL'!BO:BO,"NO HAY REFERENCIA") -> 90 | EV2: =_xlfn.XLOOKUP(B2,'BASE DE EXCEL'!$C:$C,'BASE DE EXCEL'!BP:BP,"NO HAY REFERENCIA") -> 586894.97 | EW2: =_xlfn.XLOOKUP(B2,'BASE DE EXCEL'!$C:$C,'BASE DE EXCEL'!BQ:BQ,"NO HAY REFERENCIA") -> PIEZA,PIEZA | EX2: =_xlfn.XLOOKUP(B2,'BASE DE EXCEL'!$C:$C,'BASE DE EXCEL'!BR:BR,"NO HAY REFERENCIA") -> 0 | EY2: =_xlfn.XLOOKUP(B2,'BASE DE EXCEL'!$C:$C,'BASE DE EXCEL'!BS:BS,"NO HAY REFERENCIA") -> ISRAEL (ESTADO DE) | EZ2: =_xlfn.XLOOKUP(B2,'BASE DE EXCEL'!$C:$C,'BASE DE EXCEL'!BT:BT,"NO HAY REFERENCIA") -> PAISES BAJOS (REINO DE LOS) (HOLANDA) | FA2: =_xlfn.XLOOKUP(B2,'BASE DE EXCEL'!$C:$C,'BASE DE EXCEL'!BU:BU,"NO HAY REFERENCIA") -> ISR | FB2: =_xlfn.XLOOKUP(B2,'BASE DE EXCEL'!$C:$C,'BASE DE EXCEL'!BV:BV,"NO HAY REFERENCIA") -> ZYA | FC2: =_xlfn.XLOOKUP(B2,QUERY!$C:$C,QUERY!D:D) -> 470 | FD2: =_xlfn.XLOOKUP(B2,QUERY!$C:$C,QUERY!E:E) -> 46086 | FE2: =_xlfn.XLOOKUP(B2,QUERY!$C:$C,QUERY!F:F) -> 3 | FF2: =_xlfn.XLOOKUP(B2,QUERY!$C:$C,QUERY!G:G) -> 46080 | FG2: =_xlfn.XLOOKUP(B2,QUERY!$C:$C,QUERY!H:H) -> 46086 | FH2: =_xlfn.XLOOKUP(B2,QUERY!$C:$C,QUERY!I:I) -> 4 | FI2: =_xlfn.XLOOKUP(B2,QUERY!$C:$C,QUERY!J:J) -> 4 a 5 días | FJ2: =_xlfn.XLOOKUP(B2,QUERY!$C:$C,QUERY!K:K) -> 46087 | FK2: =_xlfn.XLOOKUP(B2,QUERY!$C:$C,QUERY!L:L) -> 5 | FL2: =_xlfn.XLOOKUP(B2,QUERY!$C:$C,QUERY!M:M) -> 4 a 5 días | FM2: =_xlfn.XLOOKUP(B2,QUERY!$C:$C,QUERY!N:N) -> 1 | FN2: =_xlfn.XLOOKUP(B2,QUERY!$C:$C,QUERY!O:O) -> 1 día o menos | FO2: =_xlfn.XLOOKUP(B2,QUERY!$C:$C,QUERY!P:P) -> 1 | FP2: =_xlfn.XLOOKUP(B2,QUERY!$C:$C,QUERY!Q:Q) -> 0 | FQ2: =_xlfn.XLOOKUP(B2,QUERY!$C:$C,QUERY!R:R) -> 1 día o menos | FR2: =_xlfn.XLOOKUP(B2,QUERY!$C:$C,QUERY!S:S) -> 46087 | FS2: =_xlfn.XLOOKUP(B2,QUERY!$C:$C,QUERY!T:T) -> 5 | FT2: =_xlfn.XLOOKUP(B2,QUERY!$C:$C,QUERY!U:U) -> 4 a 5 días | FU2: =_xlfn.XLOOKUP(B2,QUERY!$C:$C,QUERY!V:V) -> 23 | FV2: =_xlfn.XLOOKUP(B2,QUERY!$C:$C,QUERY!W:W) -> más de 16 días | FW2: =_xlfn.XLOOKUP(B2,QUERY!$C:$C,QUERY!X:X) -> 46113 | FX2: =_xlfn.XLOOKUP(B2,QUERY!$C:$C,QUERY!Y:Y) -> 3 | FY2: =_xlfn.XLOOKUP(B2,QUERY!$C:$C,QUERY!Z:Z) -> 18 | FZ2: =_xlfn.XLOOKUP(B2,QUERY!$C:$C,QUERY!AA:AA) -> más de 16 días | GA2: =_xlfn.XLOOKUP(B2,QUERY!$C:$C,QUERY!AB:AB) -> 46092 | GB2: =_xlfn.XLOOKUP(B2,QUERY!$C:$C,QUERY!AC:AC) -> 46093 | GC2: =_xlfn.XLOOKUP(B2,QUERY!$C:$C,QUERY!AD:AD) -> 15 | GD2: =_xlfn.XLOOKUP(B2,QUERY!$C:$C,QUERY!AE:AE) -> 46113 | GE2: =_xlfn.XLOOKUP(B2,QUERY!$C:$C,QUERY!AF:AF) -> 1 | GF2: =_xlfn.XLOOKUP(B2,QUERY!$C:$C,QUERY!AG:AG) -> Es anterior | GG2: =_xlfn.XLOOKUP(B2,QUERY!$C:$C,QUERY!AH:AH) -> A1 | GH2: =_xlfn.XLOOKUP(B2,QUERY!$C:$C,QUERY!AI:AI) -> KAREN MARTINEZ | GI2: =_xlfn.XLOOKUP(B2,QUERY!$C:$C,QUERY!AJ:AJ) -> 057-02191140 | GJ2: =_xlfn.XLOOKUP(B2,QUERY!$C:$C,QUERY!AK:AK) -> NULL | GK2: =_xlfn.XLOOKUP(B2,QUERY!$C:$C,QUERY!AL:AL) -> 6001223 | GL2: =_xlfn.XLOOKUP(B2,QUERY!$C:$C,QUERY!AM:AM) -> Importación | GM2: =_xlfn.XLOOKUP(B2,QUERY!$C:$C,QUERY!AN:AN) -> ESTACION BASE (CONTROLLER SENSEHUB US) | GN2: =_xlfn.XLOOKUP(B2,QUERY!$C:$C,QUERY!AO:AO) -> SIN CLASIFICACION | GO2: =_xlfn.XLOOKUP(B2,QUERY!$C:$C,QUERY!AP:AP) -> 0 | GP2: =_xlfn.XLOOKUP(B2,QUERY!$C:$C,QUERY!AQ:AQ) -> Cargas de Importación | GQ2: =_xlfn.XLOOKUP(B2,QUERY!$C:$C,QUERY!AR:AR) -> INTERVET MEXICO SA DE CV | GR2: =_xlfn.XLOOKUP(B2,QUERY!$C:$C,QUERY!AS:AS) -> 0 | GS2: =_xlfn.XLOOKUP(B2,QUERY!$C:$C,QUERY!AT:AT) -> 0 | GT2: =_xlfn.XLOOKUP(B2,QUERY!$C:$C,QUERY!AU:AU) -> 0 | GU2: =_xlfn.XLOOKUP(B2,QUERY!$C:$C,QUERY!AV:AV) -> 0 | GV2: =_xlfn.XLOOKUP(B2,QUERY!$C:$C,QUERY!AW:AW) -> REFACCIONES | GW2: =_xlfn.XLOOKUP(B2,QUERY!$C:$C,QUERY!AX:AX) -> Verde | GX2: =_xlfn.XLOOKUP(B2,QUERY!$C:$C,QUERY!AY:AY) -> NULL | GY2: =_xlfn.XLOOKUP(B2,QUERY!$C:$C,QUERY!AZ:AZ) -> 0 | GZ2: =_xlfn.XLOOKUP(B2,QUERY!$C:$C,QUERY!BA:BA) -> NISSAN 3 | HA2: =_xlfn.XLOOKUP(B2,QUERY!$C:$C,QUERY!BB:BB) -> IME850329RH2 | HB2: =_xlfn.XLOOKUP(B2,QUERY!$C:$C,QUERY!BC:BC) -> 0 | HC2: =_xlfn.XLOOKUP(B2,QUERY!$C:$C,QUERY!BD:BD) -> 0 | HD2: =_xlfn.XLOOKUP(B2,QUERY!$C:$C,QUERY!BE:BE) -> LOTE: IL20260101 | HE2: =_xlfn.XLOOKUP(B2,QUERY!$C:$C,QUERY!BF:BF) -> 90 | HF2: =_xlfn.XLOOKUP(B2,QUERY!$C:$C,QUERY!BG:BG) -> 586894.97 | HG2: =_xlfn.XLOOKUP(B2,QUERY!$C:$C,QUERY!BH:BH) -> PIEZA,PIEZA | HH2: =_xlfn.XLOOKUP(B2,QUERY!$C:$C,QUERY!BI:BI) -> 0 | HI2: =_xlfn.XLOOKUP(B2,QUERY!$C:$C,QUERY!BJ:BJ) -> ISRAEL (ESTADO DE) | HJ2: =_xlfn.XLOOKUP(B2,QUERY!$C:$C,QUERY!BK:BK) -> PAISES BAJOS (REINO DE LOS) (HOLANDA) | HK2: =_xlfn.XLOOKUP(B2,QUERY!$C:$C,QUERY!BL:BL) -> ISR | HL2: =_xlfn.XLOOKUP(B2,QUERY!$C:$C,QUERY!BM:BM) -> ZYA | HM2: =_xlfn.XLOOKUP(B2,QUERY!$C:$C,QUERY!BN:BN) -> 586895 | HN2: =_xlfn.XLOOKUP(B2,QUERY!$C:$C,QUERY!BO:BO) -> 4695.00 | HO2: =_xlfn.XLOOKUP(B2,QUERY!$C:$C,QUERY!BP:BP) -> 94655.00 | HP2: =_xlfn.XLOOKUP(B2,QUERY!$C:$C,QUERY!BQ:BQ) -> NULL | HQ2: =_xlfn.XLOOKUP(B2,QUERY!$C:$C,QUERY!BR:BR) -> 20944.87 | HR2: =_xlfn.XLOOKUP(B2,QUERY!$C:$C,QUERY!BS:BS) -> 0 | HS2: =_xlfn.XLOOKUP(B2,QUERY!$C:$C,QUERY!BT:BT) -> 0 | HT2: =_xlfn.XLOOKUP(B2,QUERY!$C:$C,QUERY!A:A) -> CIUDAD DE MÉXICO | HU2: =_xlfn.XLOOKUP(B2,QUERY!$C:$C,QUERY!B:B) -> AÉREO AICM
A3: INTERVET MEXICO SA DE CV | B3: 26-001222 | C3: 3942 | D3: 6001223 | F3: Importación | G3: A1 | H3: 16 | I3: 1069 | J3: 0 | K3: 0 | L3: 0 | M3: 0 | N3: 0 | O3: 0 | P3: 0 | Q3: 0 | R3: 470 | T3: 0 | U3: 0 | V3: 0 | W3: 0 | X3: 0 | Y3: 0 | Z3: 0 | AA3: PARTES PARA APARATO DE CONTROL (PANEL KIT FOR ED200N BLUE) | AC3: 6627 | AD3: 265.08 | AE3: 0 | AF3: 0 | AG3: 0 | AH3: 0 | AI3: 0 | AJ3: 0 | AK3: 0 | AL3: 0 | AM3: 0 | AN3: 0 | AP3: INTERVET INTERNATIONAL B.V. | AQ3: 210367184 | AR3: CIP | AS3: MXP | AT3: 0 | AU3: 0 | AV3: 0 | AW3: 85389001 | AX3: 0 | AY3: 25 | AZ3: 25 | BA3: PIEZA | BC3: ISR | BD3: ZYA | BK3: COVE267ZLBAN6 | BL3: 0 | BM3: 0 | BN3: 0 | BO3: 0 | BP3: 0 | BQ3: 0 | BR3: 0 | BS3: 0 | BT3: 0 | BU3: 0 | BV3: 0 | BW3: 0 | BX3: 0 | BY3: 0 | BZ3: 0 | CA3: 0 | CB3: 0 | CC3: 0 | CD3: 0 | CE3: PEDIENTE DE PAGO | CF3: 0 | CG3: 0 | CH3: 0 | CI3: DANIEL ULISES MORALES REYES | CJ3: KAREN MARTINEZ | CK3: =_xlfn.XLOOKUP($B$2,'BASE DE EXCEL'!C:C,'BASE DE EXCEL'!D:D,"NO HAY REFERENCIA") -> 470 | CL3: =_xlfn.XLOOKUP($B$2,'BASE DE EXCEL'!$C:$C,'BASE DE EXCEL'!F:F,"NO HAY REFERENCIA") -> 3 | CM3: =_xlfn.XLOOKUP($B$2,'BASE DE EXCEL'!$C:$C,'BASE DE EXCEL'!G:G,"NO HAY REFERENCIA") -> 46080 | CN3: =_xlfn.XLOOKUP($B$2,'BASE DE EXCEL'!$C:$C,'BASE DE EXCEL'!H:H,"NO HAY REFERENCIA") -> 46086 | CO3: =_xlfn.XLOOKUP($B$2,'BASE DE EXCEL'!$C:$C,'BASE DE EXCEL'!I:I,"NO HAY REFERENCIA") -> 4 | CP3: =_xlfn.XLOOKUP($B$2,'BASE DE EXCEL'!$C:$C,'BASE DE EXCEL'!J:J,"NO HAY REFERENCIA") -> 4 a 5 días | CQ3: =_xlfn.XLOOKUP($B$2,'BASE DE EXCEL'!$C:$C,'BASE DE EXCEL'!K:K,"NO HAY REFERENCIA") -> 46087 | CR3: =_xlfn.XLOOKUP($B$2,'BASE DE EXCEL'!$C:$C,'BASE DE EXCEL'!L:L,"NO HAY REFERENCIA") -> 5 | CS3: =_xlfn.XLOOKUP($B$2,'BASE DE EXCEL'!$C:$C,'BASE DE EXCEL'!M:M,"NO HAY REFERENCIA") -> 6 | CT3: =_xlfn.XLOOKUP($B$2,'BASE DE EXCEL'!$C:$C,'BASE DE EXCEL'!N:N,"NO HAY REFERENCIA") -> 6 a 10 días | CU3: =_xlfn.XLOOKUP($B$2,'BASE DE EXCEL'!$C:$C,'BASE DE EXCEL'!O:O,"NO HAY REFERENCIA") -> On Time | CV3: =_xlfn.XLOOKUP(B3,'BASE DE EXCEL'!$C:$C,'BASE DE EXCEL'!P:P,"NO HAY REFERENCIA") -> 6 a 10 días | CW3: =_xlfn.XLOOKUP(B3,'BASE DE EXCEL'!$C:$C,'BASE DE EXCEL'!Q:Q,"NO HAY REFERENCIA") -> 46087 | CX3: =_xlfn.XLOOKUP(B3,'BASE DE EXCEL'!$C:$C,'BASE DE EXCEL'!R:R,"NO HAY REFERENCIA") -> 6 | CY3: =_xlfn.XLOOKUP(B3,'BASE DE EXCEL'!$C:$C,'BASE DE EXCEL'!S:S,"NO HAY REFERENCIA") -> 6 a 10 días | CZ3: =_xlfn.XLOOKUP(B3,'BASE DE EXCEL'!$C:$C,'BASE DE EXCEL'!T:T,"NO HAY REFERENCIA") -> On Time | DA3: =_xlfn.XLOOKUP(B3,'BASE DE EXCEL'!$C:$C,'BASE DE EXCEL'!U:U,"NO HAY REFERENCIA") -> 7 | DB3: =_xlfn.XLOOKUP(B3,'BASE DE EXCEL'!$C:$C,'BASE DE EXCEL'!V:V,"NO HAY REFERENCIA") -> 4 a 5 días | DC3: =_xlfn.XLOOKUP(B3,'BASE DE EXCEL'!$C:$C,'BASE DE EXCEL'!W:W,"NO HAY REFERENCIA") -> NULL | DD3: =_xlfn.XLOOKUP(B3,'BASE DE EXCEL'!$C:$C,'BASE DE EXCEL'!X:X,"NO HAY REFERENCIA") -> SIN DATO | DE3: =_xlfn.XLOOKUP(B3,'BASE DE EXCEL'!$C:$C,'BASE DE EXCEL'!Y:Y,"NO HAY REFERENCIA") -> 1 | DF3: =_xlfn.XLOOKUP(B3,'BASE DE EXCEL'!$C:$C,'BASE DE EXCEL'!Z:Z,"NO HAY REFERENCIA") -> 1 día o menos | DG3: =_xlfn.XLOOKUP(B3,'BASE DE EXCEL'!$C:$C,'BASE DE EXCEL'!AA:AA,"NO HAY REFERENCIA") -> 6 | DH3: =_xlfn.XLOOKUP(B3,'BASE DE EXCEL'!$C:$C,'BASE DE EXCEL'!AB:AB,"NO HAY REFERENCIA") -> 0 | DI3: =_xlfn.XLOOKUP(B3,'BASE DE EXCEL'!$C:$C,'BASE DE EXCEL'!AC:AC,"NO HAY REFERENCIA") -> 1 día o menos | DJ3: =_xlfn.XLOOKUP(B3,'BASE DE EXCEL'!$C:$C,'BASE DE EXCEL'!AD:AD,"NO HAY REFERENCIA") -> 46113 | DK3: =_xlfn.XLOOKUP(B3,'BASE DE EXCEL'!$C:$C,'BASE DE EXCEL'!AE:AE,"NO HAY REFERENCIA") -> 5 | DL3: =_xlfn.XLOOKUP(B3,'BASE DE EXCEL'!$C:$C,'BASE DE EXCEL'!AF:AF,"NO HAY REFERENCIA") -> 18 | DM3: =_xlfn.XLOOKUP(B3,'BASE DE EXCEL'!$C:$C,'BASE DE EXCEL'!AG:AG,"NO HAY REFERENCIA") -> 46092 | DN3: =_xlfn.XLOOKUP(B3,'BASE DE EXCEL'!$C:$C,'BASE DE EXCEL'!AH:AH,"NO HAY REFERENCIA") -> 46093 | DO3: =_xlfn.XLOOKUP(B3,'BASE DE EXCEL'!$C:$C,'BASE DE EXCEL'!AI:AI,"NO HAY REFERENCIA") -> NULL | DP3: =_xlfn.XLOOKUP(B3,'BASE DE EXCEL'!$C:$C,'BASE DE EXCEL'!AJ:AJ,"NO HAY REFERENCIA") -> más de 16 días | DQ3: =_xlfn.XLOOKUP(B3,'BASE DE EXCEL'!$C:$C,'BASE DE EXCEL'!AK:AK,"NO HAY REFERENCIA") -> 46113 | DR3: =_xlfn.XLOOKUP(B3,'BASE DE EXCEL'!$C:$C,'BASE DE EXCEL'!AL:AL,"NO HAY REFERENCIA") -> 18 | DS3: =_xlfn.XLOOKUP(B3,'BASE DE EXCEL'!$C:$C,'BASE DE EXCEL'!AM:AM,"NO HAY REFERENCIA") -> más de 16 días | DT3: =_xlfn.XLOOKUP(B3,'BASE DE EXCEL'!$C:$C,'BASE DE EXCEL'!AN:AN,"NO HAY REFERENCIA") -> On Time | DU3: =_xlfn.XLOOKUP(B3,'BASE DE EXCEL'!$C:$C,'BASE DE EXCEL'!AO:AO,"NO HAY REFERENCIA") -> 1 | DV3: =_xlfn.XLOOKUP(B3,'BASE DE EXCEL'!$C:$C,'BASE DE EXCEL'!AP:AP,"NO HAY REFERENCIA") -> Es anterior | DW3: =_xlfn.XLOOKUP(B3,'BASE DE EXCEL'!$C:$C,'BASE DE EXCEL'!AQ:AQ,"NO HAY REFERENCIA") -> A1 | DX3: =_xlfn.XLOOKUP(B3,'BASE DE EXCEL'!$C:$C,'BASE DE EXCEL'!AR:AR,"NO HAY REFERENCIA") -> KAREN MARTINEZ | DY3: =_xlfn.XLOOKUP(B3,'BASE DE EXCEL'!$C:$C,'BASE DE EXCEL'!AS:AS,"NO HAY REFERENCIA") -> 057-02191140 | DZ3: =_xlfn.XLOOKUP(B3,'BASE DE EXCEL'!$C:$C,'BASE DE EXCEL'!AT:AT,"NO HAY REFERENCIA") -> NULL | EA3: =_xlfn.XLOOKUP(B3,'BASE DE EXCEL'!$C:$C,'BASE DE EXCEL'!AU:AU,"NO HAY REFERENCIA") -> 6001223 | EB3: =_xlfn.XLOOKUP(B3,'BASE DE EXCEL'!$C:$C,'BASE DE EXCEL'!AV:AV,"NO HAY REFERENCIA") -> Importación | EC3: =_xlfn.XLOOKUP(B3,'BASE DE EXCEL'!$C:$C,'BASE DE EXCEL'!AW:AW,"NO HAY REFERENCIA") -> ESTACION BASE (CONTROLLER SENSEHUB US) | ED3: =_xlfn.XLOOKUP(B3,'BASE DE EXCEL'!$C:$C,'BASE DE EXCEL'!AX:AX,"NO HAY REFERENCIA") -> SIN CLASIFICACION | EE3: =_xlfn.XLOOKUP(B3,'BASE DE EXCEL'!$C:$C,'BASE DE EXCEL'!AY:AY,"NO HAY REFERENCIA") -> 0 | EF3: =_xlfn.XLOOKUP(B3,'BASE DE EXCEL'!$C:$C,'BASE DE EXCEL'!AZ:AZ,"NO HAY REFERENCIA") -> Cargas de Importación | EG3: =_xlfn.XLOOKUP(B3,'BASE DE EXCEL'!$C:$C,'BASE DE EXCEL'!BA:BA,"NO HAY REFERENCIA") -> INTERVET MEXICO SA DE CV | EH3: =_xlfn.XLOOKUP(B3,'BASE DE EXCEL'!$C:$C,'BASE DE EXCEL'!BB:BB,"NO HAY REFERENCIA") -> 0 | EI3: =_xlfn.XLOOKUP(B3,'BASE DE EXCEL'!$C:$C,'BASE DE EXCEL'!BC:BC,"NO HAY REFERENCIA") -> 0 | EJ3: =_xlfn.XLOOKUP(B3,'BASE DE EXCEL'!$C:$C,'BASE DE EXCEL'!BD:BD,"NO HAY REFERENCIA") -> 0 | EK3: =_xlfn.XLOOKUP(B3,'BASE DE EXCEL'!$C:$C,'BASE DE EXCEL'!BE:BE,"NO HAY REFERENCIA") -> 0 | EL3: =_xlfn.XLOOKUP(B3,'BASE DE EXCEL'!$C:$C,'BASE DE EXCEL'!BF:BF,"NO HAY REFERENCIA") -> REFACCIONES | EM3: =_xlfn.XLOOKUP(B3,'BASE DE EXCEL'!$C:$C,'BASE DE EXCEL'!BG:BG,"NO HAY REFERENCIA") -> Verde | EN3: =_xlfn.XLOOKUP(B3,'BASE DE EXCEL'!$C:$C,'BASE DE EXCEL'!BH:BH,"NO HAY REFERENCIA") -> NULL | EO3: =_xlfn.XLOOKUP(B3,'BASE DE EXCEL'!$C:$C,'BASE DE EXCEL'!BI:BI,"NO HAY REFERENCIA") -> 0 | EP3: =_xlfn.XLOOKUP(B3,'BASE DE EXCEL'!$C:$C,'BASE DE EXCEL'!BJ:BJ,"NO HAY REFERENCIA") -> NISSAN 3 | EQ3: =_xlfn.XLOOKUP(B3,'BASE DE EXCEL'!$C:$C,'BASE DE EXCEL'!BK:BK,"NO HAY REFERENCIA") -> IME850329RH2 | ER3: =_xlfn.XLOOKUP(B3,'BASE DE EXCEL'!$C:$C,'BASE DE EXCEL'!BL:BL,"NO HAY REFERENCIA") -> 0 | ES3: =_xlfn.XLOOKUP(B3,'BASE DE EXCEL'!$C:$C,'BASE DE EXCEL'!BM:BM,"NO HAY REFERENCIA") -> 0 | ET3: =_xlfn.XLOOKUP(B3,'BASE DE EXCEL'!$C:$C,'BASE DE EXCEL'!BN:BN,"NO HAY REFERENCIA") -> LOTE: IL20260101 | EU3: =_xlfn.XLOOKUP(B3,'BASE DE EXCEL'!$C:$C,'BASE DE EXCEL'!BO:BO,"NO HAY REFERENCIA") -> 90 | EV3: =_xlfn.XLOOKUP(B3,'BASE DE EXCEL'!$C:$C,'BASE DE EXCEL'!BP:BP,"NO HAY REFERENCIA") -> 586894.97 | EW3: =_xlfn.XLOOKUP(B3,'BASE DE EXCEL'!$C:$C,'BASE DE EXCEL'!BQ:BQ,"NO HAY REFERENCIA") -> PIEZA,PIEZA | EX3: =_xlfn.XLOOKUP(B3,'BASE DE EXCEL'!$C:$C,'BASE DE EXCEL'!BR:BR,"NO HAY REFERENCIA") -> 0 | EY3: =_xlfn.XLOOKUP(B3,'BASE DE EXCEL'!$C:$C,'BASE DE EXCEL'!BS:BS,"NO HAY REFERENCIA") -> ISRAEL (ESTADO DE) | EZ3: =_xlfn.XLOOKUP(B3,'BASE DE EXCEL'!$C:$C,'BASE DE EXCEL'!BT:BT,"NO HAY REFERENCIA") -> PAISES BAJOS (REINO DE LOS) (HOLANDA) | FA3: =_xlfn.XLOOKUP(B3,'BASE DE EXCEL'!$C:$C,'BASE DE EXCEL'!BU:BU,"NO HAY REFERENCIA") -> ISR | FB3: =_xlfn.XLOOKUP(B3,'BASE DE EXCEL'!$C:$C,'BASE DE EXCEL'!BV:BV,"NO HAY REFERENCIA") -> ZYA | FC3: =_xlfn.XLOOKUP(B3,QUERY!$C:$C,QUERY!D:D) -> 470 | FD3: =_xlfn.XLOOKUP(B3,QUERY!$C:$C,QUERY!E:E) -> 46086 | FE3: =_xlfn.XLOOKUP(B3,QUERY!$C:$C,QUERY!F:F) -> 3 | FF3: =_xlfn.XLOOKUP(B3,QUERY!$C:$C,QUERY!G:G) -> 46080 | FG3: =_xlfn.XLOOKUP(B3,QUERY!$C:$C,QUERY!H:H) -> 46086 | FH3: =_xlfn.XLOOKUP(B3,QUERY!$C:$C,QUERY!I:I) -> 4 | FI3: =_xlfn.XLOOKUP(B3,QUERY!$C:$C,QUERY!J:J) -> 4 a 5 días | FJ3: =_xlfn.XLOOKUP(B3,QUERY!$C:$C,QUERY!K:K) -> 46087 | FK3: =_xlfn.XLOOKUP(B3,QUERY!$C:$C,QUERY!L:L) -> 5 | FL3: =_xlfn.XLOOKUP(B3,QUERY!$C:$C,QUERY!M:M) -> 4 a 5 días | FM3: =_xlfn.XLOOKUP(B3,QUERY!$C:$C,QUERY!N:N) -> 1 | FN3: =_xlfn.XLOOKUP(B3,QUERY!$C:$C,QUERY!O:O) -> 1 día o menos | FO3: =_xlfn.XLOOKUP(B3,QUERY!$C:$C,QUERY!P:P) -> 1 | FP3: =_xlfn.XLOOKUP(B3,QUERY!$C:$C,QUERY!Q:Q) -> 0 | FQ3: =_xlfn.XLOOKUP(B3,QUERY!$C:$C,QUERY!R:R) -> 1 día o menos | FR3: =_xlfn.XLOOKUP(B3,QUERY!$C:$C,QUERY!S:S) -> 46087 | FS3: =_xlfn.XLOOKUP(B3,QUERY!$C:$C,QUERY!T:T) -> 5 | FT3: =_xlfn.XLOOKUP(B3,QUERY!$C:$C,QUERY!U:U) -> 4 a 5 días | FU3: =_xlfn.XLOOKUP(B3,QUERY!$C:$C,QUERY!V:V) -> 23 | FV3: =_xlfn.XLOOKUP(B3,QUERY!$C:$C,QUERY!W:W) -> más de 16 días | FW3: =_xlfn.XLOOKUP(B3,QUERY!$C:$C,QUERY!X:X) -> 46113 | FX3: =_xlfn.XLOOKUP(B3,QUERY!$C:$C,QUERY!Y:Y) -> 3 | FY3: =_xlfn.XLOOKUP(B3,QUERY!$C:$C,QUERY!Z:Z) -> 18 | FZ3: =_xlfn.XLOOKUP(B3,QUERY!$C:$C,QUERY!AA:AA) -> más de 16 días | GA3: =_xlfn.XLOOKUP(B3,QUERY!$C:$C,QUERY!AB:AB) -> 46092 | GB3: =_xlfn.XLOOKUP(B3,QUERY!$C:$C,QUERY!AC:AC) -> 46093 | GC3: =_xlfn.XLOOKUP(B3,QUERY!$C:$C,QUERY!AD:AD) -> 15 | GD3: =_xlfn.XLOOKUP(B3,QUERY!$C:$C,QUERY!AE:AE) -> 46113 | GE3: =_xlfn.XLOOKUP(B3,QUERY!$C:$C,QUERY!AF:AF) -> 1 | GF3: =_xlfn.XLOOKUP(B3,QUERY!$C:$C,QUERY!AG:AG) -> Es anterior | GG3: =_xlfn.XLOOKUP(B3,QUERY!$C:$C,QUERY!AH:AH) -> A1 | GH3: =_xlfn.XLOOKUP(B3,QUERY!$C:$C,QUERY!AI:AI) -> KAREN MARTINEZ | GI3: =_xlfn.XLOOKUP(B3,QUERY!$C:$C,QUERY!AJ:AJ) -> 057-02191140 | GJ3: =_xlfn.XLOOKUP(B3,QUERY!$C:$C,QUERY!AK:AK) -> NULL | GK3: =_xlfn.XLOOKUP(B3,QUERY!$C:$C,QUERY!AL:AL) -> 6001223 | GL3: =_xlfn.XLOOKUP(B3,QUERY!$C:$C,QUERY!AM:AM) -> Importación | GM3: =_xlfn.XLOOKUP(B3,QUERY!$C:$C,QUERY!AN:AN) -> ESTACION BASE (CONTROLLER SENSEHUB US) | GN3: =_xlfn.XLOOKUP(B3,QUERY!$C:$C,QUERY!AO:AO) -> SIN CLASIFICACION | GO3: =_xlfn.XLOOKUP(B3,QUERY!$C:$C,QUERY!AP:AP) -> 0 | GP3: =_xlfn.XLOOKUP(B3,QUERY!$C:$C,QUERY!AQ:AQ) -> Cargas de Importación | GQ3: =_xlfn.XLOOKUP(B3,QUERY!$C:$C,QUERY!AR:AR) -> INTERVET MEXICO SA DE CV | GR3: =_xlfn.XLOOKUP(B3,QUERY!$C:$C,QUERY!AS:AS) -> 0 | GS3: =_xlfn.XLOOKUP(B3,QUERY!$C:$C,QUERY!AT:AT) -> 0 | GT3: =_xlfn.XLOOKUP(B3,QUERY!$C:$C,QUERY!AU:AU) -> 0 | GU3: =_xlfn.XLOOKUP(B3,QUERY!$C:$C,QUERY!AV:AV) -> 0 | GV3: =_xlfn.XLOOKUP(B3,QUERY!$C:$C,QUERY!AW:AW) -> REFACCIONES | GW3: =_xlfn.XLOOKUP(B3,QUERY!$C:$C,QUERY!AX:AX) -> Verde | GX3: =_xlfn.XLOOKUP(B3,QUERY!$C:$C,QUERY!AY:AY) -> NULL | GY3: =_xlfn.XLOOKUP(B3,QUERY!$C:$C,QUERY!AZ:AZ) -> 0 | GZ3: =_xlfn.XLOOKUP(B3,QUERY!$C:$C,QUERY!BA:BA) -> NISSAN 3 | HA3: =_xlfn.XLOOKUP(B3,QUERY!$C:$C,QUERY!BB:BB) -> IME850329RH2 | HB3: =_xlfn.XLOOKUP(B3,QUERY!$C:$C,QUERY!BC:BC) -> 0 | HC3: =_xlfn.XLOOKUP(B3,QUERY!$C:$C,QUERY!BD:BD) -> 0 | HD3: =_xlfn.XLOOKUP(B3,QUERY!$C:$C,QUERY!BE:BE) -> LOTE: IL20260101 | HE3: =_xlfn.XLOOKUP(B3,QUERY!$C:$C,QUERY!BF:BF) -> 90 | HF3: =_xlfn.XLOOKUP(B3,QUERY!$C:$C,QUERY!BG:BG) -> 586894.97 | HG3: =_xlfn.XLOOKUP(B3,QUERY!$C:$C,QUERY!BH:BH) -> PIEZA,PIEZA | HH3: =_xlfn.XLOOKUP(B3,QUERY!$C:$C,QUERY!BI:BI) -> 0 | HI3: =_xlfn.XLOOKUP(B3,QUERY!$C:$C,QUERY!BJ:BJ) -> ISRAEL (ESTADO DE) | HJ3: =_xlfn.XLOOKUP(B3,QUERY!$C:$C,QUERY!BK:BK) -> PAISES BAJOS (REINO DE LOS) (HOLANDA) | HK3: =_xlfn.XLOOKUP(B3,QUERY!$C:$C,QUERY!BL:BL) -> ISR | HL3: =_xlfn.XLOOKUP(B3,QUERY!$C:$C,QUERY!BM:BM) -> ZYA | HM3: =_xlfn.XLOOKUP(B3,QUERY!$C:$C,QUERY!BN:BN) -> 586895 | HN3: =_xlfn.XLOOKUP(B3,QUERY!$C:$C,QUERY!BO:BO) -> 4695.00 | HO3: =_xlfn.XLOOKUP(B3,QUERY!$C:$C,QUERY!BP:BP) -> 94655.00 | HP3: =_xlfn.XLOOKUP(B3,QUERY!$C:$C,QUERY!BQ:BQ) -> NULL | HQ3: =_xlfn.XLOOKUP(B3,QUERY!$C:$C,QUERY!BR:BR) -> 20944.87 | HR3: =_xlfn.XLOOKUP(B3,QUERY!$C:$C,QUERY!BS:BS) -> 0 | HS3: =_xlfn.XLOOKUP(B3,QUERY!$C:$C,QUERY!BT:BT) -> 0 | HT3: =_xlfn.XLOOKUP(B3,QUERY!$C:$C,QUERY!A:A) -> CIUDAD DE MÉXICO | HU3: =_xlfn.XLOOKUP(B3,QUERY!$C:$C,QUERY!B:B) -> AÉREO AICM
A4: INTERVET MEXICO SA DE CV | B4: 26-002651 | C4: 3942 | D4: 6002421 | F4: Importación | G4: A1 | H4: 0 | I4: 0 | J4: 0 | K4: 0 | L4: 0 | M4: 0 | N4: 0 | O4: 0 | P4: 17.2723 | Q4: 128 | R4: 470 | T4: 1 BULTOS | U4: 356771 | V4: 356771 | W4: 0 | X4: 0 | Y4: 0 | Z4: 0 | AA4: OTOMAX | AC4: 356771 | AD4: 122.14002 | AE4: 808 | AF4: 0 | AG4: 0 | AH4: 0 | AI4: 53 | AJ4: 462 | AK4: 0 | AL4: 0 | AM4: 330 | AN4: 845 | AO4: Cliente | AP4: INTERVET INTERNATIONAL BV | AQ4: 210372466 | AR4: CIP | AS4: MXP | AT4: 125-21466701 | AU4: 1073938896 | AV4: TEC | AW4: 30042099 | AX4: 0 | AY4: 2921 | AZ4: 2921 | BA4: PIEZA | BC4: DEU | BD4: ZYA | BE4: DESADUANAMIENTO LIBRE | BG4: 4.7002012e+16 | BH4: A1 | BI4: MERCANCIA EN BUEN ESTADO | BJ4: FACTURA COMERCIAL 210372466 DE | BK4: COVE2682GPM92 | BL4: 45913 | BM4: 0 | BN4: 0 | BO4: 0 | BP4: 0 | BQ4: 0 | BR4: 0 | BS4: 0 | BT4: 0 | BU4: 0 | BV4: 0 | BW4: 0 | BX4: 0 | BY4: 0 | BZ4: 0 | CA4: 0 | CB4: 5300 | CC4: 1272 | CD4: 30905.43 | CE4: PEDIENTE DE PAGO | CF4: 30905.43 | CG4: 0 | CH4: 0 | CI4: YAIR JOSE MIRANDA ARANO | CJ4: KAREN MARTINEZ | CK4: =_xlfn.XLOOKUP($B$2,'BASE DE EXCEL'!C:C,'BASE DE EXCEL'!D:D,"NO HAY REFERENCIA") -> 470 | CL4: =_xlfn.XLOOKUP($B$2,'BASE DE EXCEL'!$C:$C,'BASE DE EXCEL'!F:F,"NO HAY REFERENCIA") -> 3 | CM4: =_xlfn.XLOOKUP($B$2,'BASE DE EXCEL'!$C:$C,'BASE DE EXCEL'!G:G,"NO HAY REFERENCIA") -> 46080 | CN4: =_xlfn.XLOOKUP($B$2,'BASE DE EXCEL'!$C:$C,'BASE DE EXCEL'!H:H,"NO HAY REFERENCIA") -> 46086 | CO4: =_xlfn.XLOOKUP($B$2,'BASE DE EXCEL'!$C:$C,'BASE DE EXCEL'!I:I,"NO HAY REFERENCIA") -> 4 | CP4: =_xlfn.XLOOKUP($B$2,'BASE DE EXCEL'!$C:$C,'BASE DE EXCEL'!J:J,"NO HAY REFERENCIA") -> 4 a 5 días | CQ4: =_xlfn.XLOOKUP($B$2,'BASE DE EXCEL'!$C:$C,'BASE DE EXCEL'!K:K,"NO HAY REFERENCIA") -> 46087 | CR4: =_xlfn.XLOOKUP($B$2,'BASE DE EXCEL'!$C:$C,'BASE DE EXCEL'!L:L,"NO HAY REFERENCIA") -> 5 | CS4: =_xlfn.XLOOKUP($B$2,'BASE DE EXCEL'!$C:$C,'BASE DE EXCEL'!M:M,"NO HAY REFERENCIA") -> 6 | CT4: =_xlfn.XLOOKUP($B$2,'BASE DE EXCEL'!$C:$C,'BASE DE EXCEL'!N:N,"NO HAY REFERENCIA") -> 6 a 10 días | CU4: =_xlfn.XLOOKUP($B$2,'BASE DE EXCEL'!$C:$C,'BASE DE EXCEL'!O:O,"NO HAY REFERENCIA") -> On Time | CV4: =_xlfn.XLOOKUP(B4,'BASE DE EXCEL'!$C:$C,'BASE DE EXCEL'!P:P,"NO HAY REFERENCIA") -> 6 a 10 días | CW4: =_xlfn.XLOOKUP(B4,'BASE DE EXCEL'!$C:$C,'BASE DE EXCEL'!Q:Q,"NO HAY REFERENCIA") -> 46142 | CX4: =_xlfn.XLOOKUP(B4,'BASE DE EXCEL'!$C:$C,'BASE DE EXCEL'!R:R,"NO HAY REFERENCIA") -> 9 | CY4: =_xlfn.XLOOKUP(B4,'BASE DE EXCEL'!$C:$C,'BASE DE EXCEL'!S:S,"NO HAY REFERENCIA") -> 6 a 10 días | CZ4: =_xlfn.XLOOKUP(B4,'BASE DE EXCEL'!$C:$C,'BASE DE EXCEL'!T:T,"NO HAY REFERENCIA") -> On Time | DA4: =_xlfn.XLOOKUP(B4,'BASE DE EXCEL'!$C:$C,'BASE DE EXCEL'!U:U,"NO HAY REFERENCIA") -> 10 | DB4: =_xlfn.XLOOKUP(B4,'BASE DE EXCEL'!$C:$C,'BASE DE EXCEL'!V:V,"NO HAY REFERENCIA") -> 6 a 10 días | DC4: =_xlfn.XLOOKUP(B4,'BASE DE EXCEL'!$C:$C,'BASE DE EXCEL'!W:W,"NO HAY REFERENCIA") -> 14 | DD4: =_xlfn.XLOOKUP(B4,'BASE DE EXCEL'!$C:$C,'BASE DE EXCEL'!X:X,"NO HAY REFERENCIA") -> 11 a 15 días | DE4: =_xlfn.XLOOKUP(B4,'BASE DE EXCEL'!$C:$C,'BASE DE EXCEL'!Y:Y,"NO HAY REFERENCIA") -> 1 | DF4: =_xlfn.XLOOKUP(B4,'BASE DE EXCEL'!$C:$C,'BASE DE EXCEL'!Z:Z,"NO HAY REFERENCIA") -> 1 día o menos | DG4: =_xlfn.XLOOKUP(B4,'BASE DE EXCEL'!$C:$C,'BASE DE EXCEL'!AA:AA,"NO HAY REFERENCIA") -> 9 | DH4: =_xlfn.XLOOKUP(B4,'BASE DE EXCEL'!$C:$C,'BASE DE EXCEL'!AB:AB,"NO HAY REFERENCIA") -> 0 | DI4: =_xlfn.XLOOKUP(B4,'BASE DE EXCEL'!$C:$C,'BASE DE EXCEL'!AC:AC,"NO HAY REFERENCIA") -> 1 día o menos | DJ4: =_xlfn.XLOOKUP(B4,'BASE DE EXCEL'!$C:$C,'BASE DE EXCEL'!AD:AD,"NO HAY REFERENCIA") -> 46150 | DK4: =_xlfn.XLOOKUP(B4,'BASE DE EXCEL'!$C:$C,'BASE DE EXCEL'!AE:AE,"NO HAY REFERENCIA") -> 8 | DL4: =_xlfn.XLOOKUP(B4,'BASE DE EXCEL'!$C:$C,'BASE DE EXCEL'!AF:AF,"NO HAY REFERENCIA") -> 6 | DM4: =_xlfn.XLOOKUP(B4,'BASE DE EXCEL'!$C:$C,'BASE DE EXCEL'!AG:AG,"NO HAY REFERENCIA") -> 46150 | DN4: =_xlfn.XLOOKUP(B4,'BASE DE EXCEL'!$C:$C,'BASE DE EXCEL'!AH:AH,"NO HAY REFERENCIA") -> 46150 | DO4: =_xlfn.XLOOKUP(B4,'BASE DE EXCEL'!$C:$C,'BASE DE EXCEL'!AI:AI,"NO HAY REFERENCIA") -> 0 | DP4: =_xlfn.XLOOKUP(B4,'BASE DE EXCEL'!$C:$C,'BASE DE EXCEL'!AJ:AJ,"NO HAY REFERENCIA") -> 6 a 10 días | DQ4: =_xlfn.XLOOKUP(B4,'BASE DE EXCEL'!$C:$C,'BASE DE EXCEL'!AK:AK,"NO HAY REFERENCIA") -> 46150 | DR4: =_xlfn.XLOOKUP(B4,'BASE DE EXCEL'!$C:$C,'BASE DE EXCEL'!AL:AL,"NO HAY REFERENCIA") -> 6 | DS4: =_xlfn.XLOOKUP(B4,'BASE DE EXCEL'!$C:$C,'BASE DE EXCEL'!AM:AM,"NO HAY REFERENCIA") -> 6 a 10 días | DT4: =_xlfn.XLOOKUP(B4,'BASE DE EXCEL'!$C:$C,'BASE DE EXCEL'!AN:AN,"NO HAY REFERENCIA") -> On Time | DU4: =_xlfn.XLOOKUP(B4,'BASE DE EXCEL'!$C:$C,'BASE DE EXCEL'!AO:AO,"NO HAY REFERENCIA") -> 1 | DV4: =_xlfn.XLOOKUP(B4,'BASE DE EXCEL'!$C:$C,'BASE DE EXCEL'!AP:AP,"NO HAY REFERENCIA") -> Es anterior | DW4: =_xlfn.XLOOKUP(B4,'BASE DE EXCEL'!$C:$C,'BASE DE EXCEL'!AQ:AQ,"NO HAY REFERENCIA") -> A1 | DX4: =_xlfn.XLOOKUP(B4,'BASE DE EXCEL'!$C:$C,'BASE DE EXCEL'!AR:AR,"NO HAY REFERENCIA") -> KAREN MARTINEZ | DY4: =_xlfn.XLOOKUP(B4,'BASE DE EXCEL'!$C:$C,'BASE DE EXCEL'!AS:AS,"NO HAY REFERENCIA") -> 125-21466701 | DZ4: =_xlfn.XLOOKUP(B4,'BASE DE EXCEL'!$C:$C,'BASE DE EXCEL'!AT:AT,"NO HAY REFERENCIA") -> 1073938896 | EA4: =_xlfn.XLOOKUP(B4,'BASE DE EXCEL'!$C:$C,'BASE DE EXCEL'!AU:AU,"NO HAY REFERENCIA") -> 6002421 | EB4: =_xlfn.XLOOKUP(B4,'BASE DE EXCEL'!$C:$C,'BASE DE EXCEL'!AV:AV,"NO HAY REFERENCIA") -> Importación | EC4: =_xlfn.XLOOKUP(B4,'BASE DE EXCEL'!$C:$C,'BASE DE EXCEL'!AW:AW,"NO HAY REFERENCIA") -> OTOMAX | ED4: =_xlfn.XLOOKUP(B4,'BASE DE EXCEL'!$C:$C,'BASE DE EXCEL'!AX:AX,"NO HAY REFERENCIA") -> SIN CLASIFICACION | EE4: =_xlfn.XLOOKUP(B4,'BASE DE EXCEL'!$C:$C,'BASE DE EXCEL'!AY:AY,"NO HAY REFERENCIA") -> 0 | EF4: =_xlfn.XLOOKUP(B4,'BASE DE EXCEL'!$C:$C,'BASE DE EXCEL'!AZ:AZ,"NO HAY REFERENCIA") -> Cargas de Importación | EG4: =_xlfn.XLOOKUP(B4,'BASE DE EXCEL'!$C:$C,'BASE DE EXCEL'!BA:BA,"NO HAY REFERENCIA") -> INTERVET MEXICO SA DE CV | EH4: =_xlfn.XLOOKUP(B4,'BASE DE EXCEL'!$C:$C,'BASE DE EXCEL'!BB:BB,"NO HAY REFERENCIA") -> 0 | EI4: =_xlfn.XLOOKUP(B4,'BASE DE EXCEL'!$C:$C,'BASE DE EXCEL'!BC:BC,"NO HAY REFERENCIA") -> 0 | EJ4: =_xlfn.XLOOKUP(B4,'BASE DE EXCEL'!$C:$C,'BASE DE EXCEL'!BD:BD,"NO HAY REFERENCIA") -> 0 | EK4: =_xlfn.XLOOKUP(B4,'BASE DE EXCEL'!$C:$C,'BASE DE EXCEL'!BE:BE,"NO HAY REFERENCIA") -> 0 | EL4: =_xlfn.XLOOKUP(B4,'BASE DE EXCEL'!$C:$C,'BASE DE EXCEL'!BF:BF,"NO HAY REFERENCIA") -> MATERIA PRIMA | EM4: =_xlfn.XLOOKUP(B4,'BASE DE EXCEL'!$C:$C,'BASE DE EXCEL'!BG:BG,"NO HAY REFERENCIA") -> Verde | EN4: =_xlfn.XLOOKUP(B4,'BASE DE EXCEL'!$C:$C,'BASE DE EXCEL'!BH:BH,"NO HAY REFERENCIA") -> NULL | EO4: =_xlfn.XLOOKUP(B4,'BASE DE EXCEL'!$C:$C,'BASE DE EXCEL'!BI:BI,"NO HAY REFERENCIA") -> 0 | EP4: =_xlfn.XLOOKUP(B4,'BASE DE EXCEL'!$C:$C,'BASE DE EXCEL'!BJ:BJ,"NO HAY REFERENCIA") -> NISSAN 6 | EQ4: =_xlfn.XLOOKUP(B4,'BASE DE EXCEL'!$C:$C,'BASE DE EXCEL'!BK:BK,"NO HAY REFERENCIA") -> IME850329RH2 | ER4: =_xlfn.XLOOKUP(B4,'BASE DE EXCEL'!$C:$C,'BASE DE EXCEL'!BL:BL,"NO HAY REFERENCIA") -> 0 | ES4: =_xlfn.XLOOKUP(B4,'BASE DE EXCEL'!$C:$C,'BASE DE EXCEL'!BM:BM,"NO HAY REFERENCIA") -> 0 | ET4: =_xlfn.XLOOKUP(B4,'BASE DE EXCEL'!$C:$C,'BASE DE EXCEL'!BN:BN,"NO HAY REFERENCIA") -> LOTE: 6507301 | EU4: =_xlfn.XLOOKUP(B4,'BASE DE EXCEL'!$C:$C,'BASE DE EXCEL'!BO:BO,"NO HAY REFERENCIA") -> 90 | EV4: =_xlfn.XLOOKUP(B4,'BASE DE EXCEL'!$C:$C,'BASE DE EXCEL'!BP:BP,"NO HAY REFERENCIA") -> 356770.94 | EW4: =_xlfn.XLOOKUP(B4,'BASE DE EXCEL'!$C:$C,'BASE DE EXCEL'!BQ:BQ,"NO HAY REFERENCIA") -> KILO | EX4: =_xlfn.XLOOKUP(B4,'BASE DE EXCEL'!$C:$C,'BASE DE EXCEL'!BR:BR,"NO HAY REFERENCIA") -> 0 | EY4: =_xlfn.XLOOKUP(B4,'BASE DE EXCEL'!$C:$C,'BASE DE EXCEL'!BS:BS,"NO HAY REFERENCIA") -> ALEMANIA (REPUBLICA FEDERAL DE) | EZ4: =_xlfn.XLOOKUP(B4,'BASE DE EXCEL'!$C:$C,'BASE DE EXCEL'!BT:BT,"NO HAY REFERENCIA") -> PAISES BAJOS (REINO DE LOS) (HOLANDA) | FA4: =_xlfn.XLOOKUP(B4,'BASE DE EXCEL'!$C:$C,'BASE DE EXCEL'!BU:BU,"NO HAY REFERENCIA") -> DEU | FB4: =_xlfn.XLOOKUP(B4,'BASE DE EXCEL'!$C:$C,'BASE DE EXCEL'!BV:BV,"NO HAY REFERENCIA") -> ZYA | FC4: =_xlfn.XLOOKUP(B4,QUERY!$C:$C,QUERY!D:D) -> 470 | FD4: =_xlfn.XLOOKUP(B4,QUERY!$C:$C,QUERY!E:E) -> 46141 | FE4: =_xlfn.XLOOKUP(B4,QUERY!$C:$C,QUERY!F:F) -> 4 | FF4: =_xlfn.XLOOKUP(B4,QUERY!$C:$C,QUERY!G:G) -> 46132 | FG4: =_xlfn.XLOOKUP(B4,QUERY!$C:$C,QUERY!H:H) -> 46141 | FH4: =_xlfn.XLOOKUP(B4,QUERY!$C:$C,QUERY!I:I) -> 7 | FI4: =_xlfn.XLOOKUP(B4,QUERY!$C:$C,QUERY!J:J) -> 6 a 10 días | FJ4: =_xlfn.XLOOKUP(B4,QUERY!$C:$C,QUERY!K:K) -> 46142 | FK4: =_xlfn.XLOOKUP(B4,QUERY!$C:$C,QUERY!L:L) -> 8 | FL4: =_xlfn.XLOOKUP(B4,QUERY!$C:$C,QUERY!M:M) -> 6 a 10 días | FM4: =_xlfn.XLOOKUP(B4,QUERY!$C:$C,QUERY!N:N) -> 1 | FN4: =_xlfn.XLOOKUP(B4,QUERY!$C:$C,QUERY!O:O) -> 1 día o menos | FO4: =_xlfn.XLOOKUP(B4,QUERY!$C:$C,QUERY!P:P) -> 1 | FP4: =_xlfn.XLOOKUP(B4,QUERY!$C:$C,QUERY!Q:Q) -> 0 | FQ4: =_xlfn.XLOOKUP(B4,QUERY!$C:$C,QUERY!R:R) -> 1 día o menos | FR4: =_xlfn.XLOOKUP(B4,QUERY!$C:$C,QUERY!S:S) -> 46142 | FS4: =_xlfn.XLOOKUP(B4,QUERY!$C:$C,QUERY!T:T) -> 8 | FT4: =_xlfn.XLOOKUP(B4,QUERY!$C:$C,QUERY!U:U) -> 6 a 10 días | FU4: =_xlfn.XLOOKUP(B4,QUERY!$C:$C,QUERY!V:V) -> 14 | FV4: =_xlfn.XLOOKUP(B4,QUERY!$C:$C,QUERY!W:W) -> 11 a 15 días | FW4: =_xlfn.XLOOKUP(B4,QUERY!$C:$C,QUERY!X:X) -> 46150 | FX4: =_xlfn.XLOOKUP(B4,QUERY!$C:$C,QUERY!Y:Y) -> 6 | FY4: =_xlfn.XLOOKUP(B4,QUERY!$C:$C,QUERY!Z:Z) -> 6 | FZ4: =_xlfn.XLOOKUP(B4,QUERY!$C:$C,QUERY!AA:AA) -> 6 a 10 días | GA4: =_xlfn.XLOOKUP(B4,QUERY!$C:$C,QUERY!AB:AB) -> 46150 | GB4: =_xlfn.XLOOKUP(B4,QUERY!$C:$C,QUERY!AC:AC) -> 46150 | GC4: =_xlfn.XLOOKUP(B4,QUERY!$C:$C,QUERY!AD:AD) -> 0 | GD4: =_xlfn.XLOOKUP(B4,QUERY!$C:$C,QUERY!AE:AE) -> 46150 | GE4: =_xlfn.XLOOKUP(B4,QUERY!$C:$C,QUERY!AF:AF) -> 1 | GF4: =_xlfn.XLOOKUP(B4,QUERY!$C:$C,QUERY!AG:AG) -> Es anterior | GG4: =_xlfn.XLOOKUP(B4,QUERY!$C:$C,QUERY!AH:AH) -> A1 | GH4: =_xlfn.XLOOKUP(B4,QUERY!$C:$C,QUERY!AI:AI) -> KAREN MARTINEZ | GI4: =_xlfn.XLOOKUP(B4,QUERY!$C:$C,QUERY!AJ:AJ) -> 125-21466701 | GJ4: =_xlfn.XLOOKUP(B4,QUERY!$C:$C,QUERY!AK:AK) -> 1073938896 | GK4: =_xlfn.XLOOKUP(B4,QUERY!$C:$C,QUERY!AL:AL) -> 6002421 | GL4: =_xlfn.XLOOKUP(B4,QUERY!$C:$C,QUERY!AM:AM) -> Importación | GM4: =_xlfn.XLOOKUP(B4,QUERY!$C:$C,QUERY!AN:AN) -> OTOMAX | GN4: =_xlfn.XLOOKUP(B4,QUERY!$C:$C,QUERY!AO:AO) -> SIN CLASIFICACION | GO4: =_xlfn.XLOOKUP(B4,QUERY!$C:$C,QUERY!AP:AP) -> 0 | GP4: =_xlfn.XLOOKUP(B4,QUERY!$C:$C,QUERY!AQ:AQ) -> Cargas de Importación | GQ4: =_xlfn.XLOOKUP(B4,QUERY!$C:$C,QUERY!AR:AR) -> INTERVET MEXICO SA DE CV | GR4: =_xlfn.XLOOKUP(B4,QUERY!$C:$C,QUERY!AS:AS) -> 0 | GS4: =_xlfn.XLOOKUP(B4,QUERY!$C:$C,QUERY!AT:AT) -> 0 | GT4: =_xlfn.XLOOKUP(B4,QUERY!$C:$C,QUERY!AU:AU) -> 0 | GU4: =_xlfn.XLOOKUP(B4,QUERY!$C:$C,QUERY!AV:AV) -> 0 | GV4: =_xlfn.XLOOKUP(B4,QUERY!$C:$C,QUERY!AW:AW) -> MATERIA PRIMA | GW4: =_xlfn.XLOOKUP(B4,QUERY!$C:$C,QUERY!AX:AX) -> Verde | GX4: =_xlfn.XLOOKUP(B4,QUERY!$C:$C,QUERY!AY:AY) -> NULL | GY4: =_xlfn.XLOOKUP(B4,QUERY!$C:$C,QUERY!AZ:AZ) -> 0 | GZ4: =_xlfn.XLOOKUP(B4,QUERY!$C:$C,QUERY!BA:BA) -> NISSAN 6 | HA4: =_xlfn.XLOOKUP(B4,QUERY!$C:$C,QUERY!BB:BB) -> IME850329RH2 | HB4: =_xlfn.XLOOKUP(B4,QUERY!$C:$C,QUERY!BC:BC) -> 0 | HC4: =_xlfn.XLOOKUP(B4,QUERY!$C:$C,QUERY!BD:BD) -> 0 | HD4: =_xlfn.XLOOKUP(B4,QUERY!$C:$C,QUERY!BE:BE) -> LOTE: 6507301 | HE4: =_xlfn.XLOOKUP(B4,QUERY!$C:$C,QUERY!BF:BF) -> 90 | HF4: =_xlfn.XLOOKUP(B4,QUERY!$C:$C,QUERY!BG:BG) -> 356770.94 | HG4: =_xlfn.XLOOKUP(B4,QUERY!$C:$C,QUERY!BH:BH) -> KILO | HH4: =_xlfn.XLOOKUP(B4,QUERY!$C:$C,QUERY!BI:BI) -> 0 | HI4: =_xlfn.XLOOKUP(B4,QUERY!$C:$C,QUERY!BJ:BJ) -> ALEMANIA (REPUBLICA FEDERAL DE) | HJ4: =_xlfn.XLOOKUP(B4,QUERY!$C:$C,QUERY!BK:BK) -> PAISES BAJOS (REINO DE LOS) (HOLANDA) | HK4: =_xlfn.XLOOKUP(B4,QUERY!$C:$C,QUERY!BL:BL) -> DEU | HL4: =_xlfn.XLOOKUP(B4,QUERY!$C:$C,QUERY!BM:BM) -> ZYA | HM4: =_xlfn.XLOOKUP(B4,QUERY!$C:$C,QUERY!BN:BN) -> 356771 | HN4: =_xlfn.XLOOKUP(B4,QUERY!$C:$C,QUERY!BO:BO) -> 462.00 | HO4: =_xlfn.XLOOKUP(B4,QUERY!$C:$C,QUERY!BP:BP) -> NULL | HP4: =_xlfn.XLOOKUP(B4,QUERY!$C:$C,QUERY!BQ:BQ) -> NULL | HQ4: =_xlfn.XLOOKUP(B4,QUERY!$C:$C,QUERY!BR:BR) -> 30905.43 | HR4: =_xlfn.XLOOKUP(B4,QUERY!$C:$C,QUERY!BS:BS) -> 0 | HS4: =_xlfn.XLOOKUP(B4,QUERY!$C:$C,QUERY!BT:BT) -> 0 | HT4: =_xlfn.XLOOKUP(B4,QUERY!$C:$C,QUERY!A:A) -> CIUDAD DE MÉXICO | HU4: =_xlfn.XLOOKUP(B4,QUERY!$C:$C,QUERY!B:B) -> AÉREO AICM
A5: INTERVET MEXICO SA DE CV | B5: VER-25-1248 | C5: 3942 | D5: 6000072 | F5: Importación | G5: A1 | H5: 0 | I5: 0 | J5: 0 | K5: 0 | L5: 0 | M5: 0 | N5: 0 | O5: 0 | P5: 18.0012 | Q5: 5918 | R5: 430 | S5: CAAU4072651 | T5: 1 CONTENEDOR DE 40' RH | U5: 3997122 | V5: 3997122 | W5: 0 | X5: 0 | Y5: 0 | Z5: 0 | AA5: CEFA SAFE (MEDICAMENTO DOSIFICADO DE USO VETERINARIO) | AC5: 211379 | AD5: 2486.8118 | AE5: 808 | AF5: 0 | AG5: 0 | AH5: 0 | AI5: 53 | AJ5: 462 | AK5: 0 | AL5: 0 | AM5: 330 | AN5: 845 | AO5: Cliente | AP5: INTERVET INTERNATIONAL BV | AQ5: 210358508 | AR5: CIP | AS5: MXP | AT5: HLCUANR251131095 | AV5: TEC | AW5: 30042099 | AX5: 0 | AY5: 85 | AZ5: 85 | BA5: PIEZA | BC5: ZYA | BD5: ZYA | BE5: DESADUANAMIENTO LIBRE | BF5: NINGUNO | BG5: 43064022026004190, 4306402202 | BH5: A1, A1, A1, A1, A1 | BJ5: DE CONFORMIDAD CON EL ART. 36- | BK5: COVE267WG87A1 | BL5: 41647 | BM5: 0 | BN5: 0 | BO5: 0 | BP5: 0 | BQ5: 0 | BR5: 0 | BS5: 0 | BT5: 0 | BU5: 0 | BV5: 0 | BW5: 0 | BX5: 20545.92 | BY5: 0 | BZ5: 0 | CA5: 0 | CB5: 5779.19 | CC5: 1367.87 | CD5: 139939.61 | CE5: PAGADO | CF5: 139939.61 | CG5: 139939.61 | CH5: 0 | CI5: ZULEIMA PEREZ RUIZ | CJ5: ZULEIMA PEREZ RUIZ | CK5: =_xlfn.XLOOKUP($B$2,'BASE DE EXCEL'!C:C,'BASE DE EXCEL'!D:D,"NO HAY REFERENCIA") -> 470 | CL5: =_xlfn.XLOOKUP($B$2,'BASE DE EXCEL'!$C:$C,'BASE DE EXCEL'!F:F,"NO HAY REFERENCIA") -> 3 | CM5: =_xlfn.XLOOKUP($B$2,'BASE DE EXCEL'!$C:$C,'BASE DE EXCEL'!G:G,"NO HAY REFERENCIA") -> 46080 | CN5: =_xlfn.XLOOKUP($B$2,'BASE DE EXCEL'!$C:$C,'BASE DE EXCEL'!H:H,"NO HAY REFERENCIA") -> 46086 | CO5: =_xlfn.XLOOKUP($B$2,'BASE DE EXCEL'!$C:$C,'BASE DE EXCEL'!I:I,"NO HAY REFERENCIA") -> 4 | CP5: =_xlfn.XLOOKUP($B$2,'BASE DE EXCEL'!$C:$C,'BASE DE EXCEL'!J:J,"NO HAY REFERENCIA") -> 4 a 5 días | CQ5: =_xlfn.XLOOKUP($B$2,'BASE DE EXCEL'!$C:$C,'BASE DE EXCEL'!K:K,"NO HAY REFERENCIA") -> 46087 | CR5: =_xlfn.XLOOKUP($B$2,'BASE DE EXCEL'!$C:$C,'BASE DE EXCEL'!L:L,"NO HAY REFERENCIA") -> 5 | CS5: =_xlfn.XLOOKUP($B$2,'BASE DE EXCEL'!$C:$C,'BASE DE EXCEL'!M:M,"NO HAY REFERENCIA") -> 6 | CT5: =_xlfn.XLOOKUP($B$2,'BASE DE EXCEL'!$C:$C,'BASE DE EXCEL'!N:N,"NO HAY REFERENCIA") -> 6 a 10 días | CU5: =_xlfn.XLOOKUP($B$2,'BASE DE EXCEL'!$C:$C,'BASE DE EXCEL'!O:O,"NO HAY REFERENCIA") -> On Time | CV5: =_xlfn.XLOOKUP(B5,'BASE DE EXCEL'!$C:$C,'BASE DE EXCEL'!P:P,"NO HAY REFERENCIA") -> 4 a 5 días | CW5: =_xlfn.XLOOKUP(B5,'BASE DE EXCEL'!$C:$C,'BASE DE EXCEL'!Q:Q,"NO HAY REFERENCIA") -> 46031 | CX5: =_xlfn.XLOOKUP(B5,'BASE DE EXCEL'!$C:$C,'BASE DE EXCEL'!R:R,"NO HAY REFERENCIA") -> 5 | CY5: =_xlfn.XLOOKUP(B5,'BASE DE EXCEL'!$C:$C,'BASE DE EXCEL'!S:S,"NO HAY REFERENCIA") -> 4 a 5 días | CZ5: =_xlfn.XLOOKUP(B5,'BASE DE EXCEL'!$C:$C,'BASE DE EXCEL'!T:T,"NO HAY REFERENCIA") -> On Time | DA5: =_xlfn.XLOOKUP(B5,'BASE DE EXCEL'!$C:$C,'BASE DE EXCEL'!U:U,"NO HAY REFERENCIA") -> 6 | DB5: =_xlfn.XLOOKUP(B5,'BASE DE EXCEL'!$C:$C,'BASE DE EXCEL'!V:V,"NO HAY REFERENCIA") -> 4 a 5 días | DC5: =_xlfn.XLOOKUP(B5,'BASE DE EXCEL'!$C:$C,'BASE DE EXCEL'!W:W,"NO HAY REFERENCIA") -> 9 | DD5: =_xlfn.XLOOKUP(B5,'BASE DE EXCEL'!$C:$C,'BASE DE EXCEL'!X:X,"NO HAY REFERENCIA") -> 6 a 10 días | DE5: =_xlfn.XLOOKUP(B5,'BASE DE EXCEL'!$C:$C,'BASE DE EXCEL'!Y:Y,"NO HAY REFERENCIA") -> 1 | DF5: =_xlfn.XLOOKUP(B5,'BASE DE EXCEL'!$C:$C,'BASE DE EXCEL'!Z:Z,"NO HAY REFERENCIA") -> 1 día o menos | DG5: =_xlfn.XLOOKUP(B5,'BASE DE EXCEL'!$C:$C,'BASE DE EXCEL'!AA:AA,"NO HAY REFERENCIA") -> 4 | DH5: =_xlfn.XLOOKUP(B5,'BASE DE EXCEL'!$C:$C,'BASE DE EXCEL'!AB:AB,"NO HAY REFERENCIA") -> 1 | DI5: =_xlfn.XLOOKUP(B5,'BASE DE EXCEL'!$C:$C,'BASE DE EXCEL'!AC:AC,"NO HAY REFERENCIA") -> 1 día o menos | DJ5: =_xlfn.XLOOKUP(B5,'BASE DE EXCEL'!$C:$C,'BASE DE EXCEL'!AD:AD,"NO HAY REFERENCIA") -> 46038 | DK5: =_xlfn.XLOOKUP(B5,'BASE DE EXCEL'!$C:$C,'BASE DE EXCEL'!AE:AE,"NO HAY REFERENCIA") -> 7 | DL5: =_xlfn.XLOOKUP(B5,'BASE DE EXCEL'!$C:$C,'BASE DE EXCEL'!AF:AF,"NO HAY REFERENCIA") -> 5 | DM5: =_xlfn.XLOOKUP(B5,'BASE DE EXCEL'!$C:$C,'BASE DE EXCEL'!AG:AG,"NO HAY REFERENCIA") -> 46038 | DN5: =_xlfn.XLOOKUP(B5,'BASE DE EXCEL'!$C:$C,'BASE DE EXCEL'!AH:AH,"NO HAY REFERENCIA") -> 46038 | DO5: =_xlfn.XLOOKUP(B5,'BASE DE EXCEL'!$C:$C,'BASE DE EXCEL'!AI:AI,"NO HAY REFERENCIA") -> 0 | DP5: =_xlfn.XLOOKUP(B5,'BASE DE EXCEL'!$C:$C,'BASE DE EXCEL'!AJ:AJ,"NO HAY REFERENCIA") -> 6 a 10 días | DQ5: =_xlfn.XLOOKUP(B5,'BASE DE EXCEL'!$C:$C,'BASE DE EXCEL'!AK:AK,"NO HAY REFERENCIA") -> 46038 | DR5: =_xlfn.XLOOKUP(B5,'BASE DE EXCEL'!$C:$C,'BASE DE EXCEL'!AL:AL,"NO HAY REFERENCIA") -> 6 | DS5: =_xlfn.XLOOKUP(B5,'BASE DE EXCEL'!$C:$C,'BASE DE EXCEL'!AM:AM,"NO HAY REFERENCIA") -> 6 a 10 días | DT5: =_xlfn.XLOOKUP(B5,'BASE DE EXCEL'!$C:$C,'BASE DE EXCEL'!AN:AN,"NO HAY REFERENCIA") -> On Time | DU5: =_xlfn.XLOOKUP(B5,'BASE DE EXCEL'!$C:$C,'BASE DE EXCEL'!AO:AO,"NO HAY REFERENCIA") -> 1 | DV5: =_xlfn.XLOOKUP(B5,'BASE DE EXCEL'!$C:$C,'BASE DE EXCEL'!AP:AP,"NO HAY REFERENCIA") -> Es anterior | DW5: =_xlfn.XLOOKUP(B5,'BASE DE EXCEL'!$C:$C,'BASE DE EXCEL'!AQ:AQ,"NO HAY REFERENCIA") -> A1 | DX5: =_xlfn.XLOOKUP(B5,'BASE DE EXCEL'!$C:$C,'BASE DE EXCEL'!AR:AR,"NO HAY REFERENCIA") -> ZULEIMA PEREZ RUIZ | DY5: =_xlfn.XLOOKUP(B5,'BASE DE EXCEL'!$C:$C,'BASE DE EXCEL'!AS:AS,"NO HAY REFERENCIA") -> HLCUANR251131095 | DZ5: =_xlfn.XLOOKUP(B5,'BASE DE EXCEL'!$C:$C,'BASE DE EXCEL'!AT:AT,"NO HAY REFERENCIA") -> NULL | EA5: =_xlfn.XLOOKUP(B5,'BASE DE EXCEL'!$C:$C,'BASE DE EXCEL'!AU:AU,"NO HAY REFERENCIA") -> 6000072 | EB5: =_xlfn.XLOOKUP(B5,'BASE DE EXCEL'!$C:$C,'BASE DE EXCEL'!AV:AV,"NO HAY REFERENCIA") -> Importación | EC5: =_xlfn.XLOOKUP(B5,'BASE DE EXCEL'!$C:$C,'BASE DE EXCEL'!AW:AW,"NO HAY REFERENCIA") -> CEFA SAFE (MEDICAMENTO DOSIFICADO DE USO VETERINARIO) | ED5: =_xlfn.XLOOKUP(B5,'BASE DE EXCEL'!$C:$C,'BASE DE EXCEL'!AX:AX,"NO HAY REFERENCIA") -> SIN CLASIFICACION | EE5: =_xlfn.XLOOKUP(B5,'BASE DE EXCEL'!$C:$C,'BASE DE EXCEL'!AY:AY,"NO HAY REFERENCIA") -> 0 | EF5: =_xlfn.XLOOKUP(B5,'BASE DE EXCEL'!$C:$C,'BASE DE EXCEL'!AZ:AZ,"NO HAY REFERENCIA") -> Cargas de Importación | EG5: =_xlfn.XLOOKUP(B5,'BASE DE EXCEL'!$C:$C,'BASE DE EXCEL'!BA:BA,"NO HAY REFERENCIA") -> INTERVET MEXICO SA DE CV | EH5: =_xlfn.XLOOKUP(B5,'BASE DE EXCEL'!$C:$C,'BASE DE EXCEL'!BB:BB,"NO HAY REFERENCIA") -> 0 | EI5: =_xlfn.XLOOKUP(B5,'BASE DE EXCEL'!$C:$C,'BASE DE EXCEL'!BC:BC,"NO HAY REFERENCIA") -> NINGUNO | EJ5: =_xlfn.XLOOKUP(B5,'BASE DE EXCEL'!$C:$C,'BASE DE EXCEL'!BD:BD,"NO HAY REFERENCIA") -> 0 | EK5: =_xlfn.XLOOKUP(B5,'BASE DE EXCEL'!$C:$C,'BASE DE EXCEL'!BE:BE,"NO HAY REFERENCIA") -> NINGUNO | EL5: =_xlfn.XLOOKUP(B5,'BASE DE EXCEL'!$C:$C,'BASE DE EXCEL'!BF:BF,"NO HAY REFERENCIA") -> PRODUCTO TERMINADO | EM5: =_xlfn.XLOOKUP(B5,'BASE DE EXCEL'!$C:$C,'BASE DE EXCEL'!BG:BG,"NO HAY REFERENCIA") -> Verde | EN5: =_xlfn.XLOOKUP(B5,'BASE DE EXCEL'!$C:$C,'BASE DE EXCEL'!BH:BH,"NO HAY REFERENCIA") -> SUPER EXPRESS DE CARGA FEDERAL S.A. DE C.V. | EO5: =_xlfn.XLOOKUP(B5,'BASE DE EXCEL'!$C:$C,'BASE DE EXCEL'!BI:BI,"NO HAY REFERENCIA") -> 0 | EP5: =_xlfn.XLOOKUP(B5,'BASE DE EXCEL'!$C:$C,'BASE DE EXCEL'!BJ:BJ,"NO HAY REFERENCIA") -> IME-T006 | EQ5: =_xlfn.XLOOKUP(B5,'BASE DE EXCEL'!$C:$C,'BASE DE EXCEL'!BK:BK,"NO HAY REFERENCIA") -> IME850329RH2 | ER5: =_xlfn.XLOOKUP(B5,'BASE DE EXCEL'!$C:$C,'BASE DE EXCEL'!BL:BL,"NO HAY REFERENCIA") -> 0 | ES5: =_xlfn.XLOOKUP(B5,'BASE DE EXCEL'!$C:$C,'BASE DE EXCEL'!BM:BM,"NO HAY REFERENCIA") -> 00,99 | ET5: =_xlfn.XLOOKUP(B5,'BASE DE EXCEL'!$C:$C,'BASE DE EXCEL'!BN:BN,"NO HAY REFERENCIA") -> LOTE: A217A05,LOTE: A219A02,LOTE: A219A01,LOTE: A217A03,LOTE: H107A01,LOTES: J550A01, J607A01,LOTE: 5677101,LOTE: A217A04 | EU5: =_xlfn.XLOOKUP(B5,'BASE DE EXCEL'!$C:$C,'BASE DE EXCEL'!BO:BO,"NO HAY REFERENCIA") -> 90 | EV5: =_xlfn.XLOOKUP(B5,'BASE DE EXCEL'!$C:$C,'BASE DE EXCEL'!BP:BP,"NO HAY REFERENCIA") -> 952448.23, 2181141.30, 863532.00 | EW5: =_xlfn.XLOOKUP(B5,'BASE DE EXCEL'!$C:$C,'BASE DE EXCEL'!BQ:BQ,"NO HAY REFERENCIA") -> KILO,KILO,KILO,KILO,KILO,KILO,KILO,KILO | EX5: =_xlfn.XLOOKUP(B5,'BASE DE EXCEL'!$C:$C,'BASE DE EXCEL'!BR:BR,"NO HAY REFERENCIA") -> 0 | EY5: =_xlfn.XLOOKUP(B5,'BASE DE EXCEL'!$C:$C,'BASE DE EXCEL'!BS:BS,"NO HAY REFERENCIA") -> ALEMANIA (REPUBLICA FEDERAL DE),PAISES BAJOS (REINO DE LOS) (HOLANDA) | EZ5: =_xlfn.XLOOKUP(B5,'BASE DE EXCEL'!$C:$C,'BASE DE EXCEL'!BT:BT,"NO HAY REFERENCIA") -> PAISES BAJOS (REINO DE LOS) (HOLANDA) | FA5: =_xlfn.XLOOKUP(B5,'BASE DE EXCEL'!$C:$C,'BASE DE EXCEL'!BU:BU,"NO HAY REFERENCIA") -> DEU,ZYA | FB5: =_xlfn.XLOOKUP(B5,'BASE DE EXCEL'!$C:$C,'BASE DE EXCEL'!BV:BV,"NO HAY REFERENCIA") -> ZYA | FC5: =_xlfn.XLOOKUP(B5,QUERY!$C:$C,QUERY!D:D) -> 430 | FD5: =_xlfn.XLOOKUP(B5,QUERY!$C:$C,QUERY!E:E) -> 46029 | FE5: =_xlfn.XLOOKUP(B5,QUERY!$C:$C,QUERY!F:F) -> 1 | FF5: =_xlfn.XLOOKUP(B5,QUERY!$C:$C,QUERY!G:G) -> 46025 | FG5: =_xlfn.XLOOKUP(B5,QUERY!$C:$C,QUERY!H:H) -> 46029 | FH5: =_xlfn.XLOOKUP(B5,QUERY!$C:$C,QUERY!I:I) -> 2 | FI5: =_xlfn.XLOOKUP(B5,QUERY!$C:$C,QUERY!J:J) -> 2 a 3 días | FJ5: =_xlfn.XLOOKUP(B5,QUERY!$C:$C,QUERY!K:K) -> 46030 | FK5: =_xlfn.XLOOKUP(B5,QUERY!$C:$C,QUERY!L:L) -> 3 | FL5: =_xlfn.XLOOKUP(B5,QUERY!$C:$C,QUERY!M:M) -> 2 a 3 días | FM5: =_xlfn.XLOOKUP(B5,QUERY!$C:$C,QUERY!N:N) -> 1 | FN5: =_xlfn.XLOOKUP(B5,QUERY!$C:$C,QUERY!O:O) -> 1 día o menos | FO5: =_xlfn.XLOOKUP(B5,QUERY!$C:$C,QUERY!P:P) -> 1 | FP5: =_xlfn.XLOOKUP(B5,QUERY!$C:$C,QUERY!Q:Q) -> 1 | FQ5: =_xlfn.XLOOKUP(B5,QUERY!$C:$C,QUERY!R:R) -> 1 día o menos | FR5: =_xlfn.XLOOKUP(B5,QUERY!$C:$C,QUERY!S:S) -> 46031 | FS5: =_xlfn.XLOOKUP(B5,QUERY!$C:$C,QUERY!T:T) -> 4 | FT5: =_xlfn.XLOOKUP(B5,QUERY!$C:$C,QUERY!U:U) -> 4 a 5 días | FU5: =_xlfn.XLOOKUP(B5,QUERY!$C:$C,QUERY!V:V) -> 9 | FV5: =_xlfn.XLOOKUP(B5,QUERY!$C:$C,QUERY!W:W) -> 6 a 10 días | FW5: =_xlfn.XLOOKUP(B5,QUERY!$C:$C,QUERY!X:X) -> 46038 | FX5: =_xlfn.XLOOKUP(B5,QUERY!$C:$C,QUERY!Y:Y) -> 5 | FY5: =_xlfn.XLOOKUP(B5,QUERY!$C:$C,QUERY!Z:Z) -> 5 | FZ5: =_xlfn.XLOOKUP(B5,QUERY!$C:$C,QUERY!AA:AA) -> 6 a 10 días | GA5: =_xlfn.XLOOKUP(B5,QUERY!$C:$C,QUERY!AB:AB) -> 46038 | GB5: =_xlfn.XLOOKUP(B5,QUERY!$C:$C,QUERY!AC:AC) -> 46038 | GC5: =_xlfn.XLOOKUP(B5,QUERY!$C:$C,QUERY!AD:AD) -> 0 | GD5: =_xlfn.XLOOKUP(B5,QUERY!$C:$C,QUERY!AE:AE) -> 46038 | GE5: =_xlfn.XLOOKUP(B5,QUERY!$C:$C,QUERY!AF:AF) -> 1 | GF5: =_xlfn.XLOOKUP(B5,QUERY!$C:$C,QUERY!AG:AG) -> Es anterior | GG5: =_xlfn.XLOOKUP(B5,QUERY!$C:$C,QUERY!AH:AH) -> A1 | GH5: =_xlfn.XLOOKUP(B5,QUERY!$C:$C,QUERY!AI:AI) -> ZULEIMA PEREZ RUIZ | GI5: =_xlfn.XLOOKUP(B5,QUERY!$C:$C,QUERY!AJ:AJ) -> HLCUANR251131095 | GJ5: =_xlfn.XLOOKUP(B5,QUERY!$C:$C,QUERY!AK:AK) -> NULL | GK5: =_xlfn.XLOOKUP(B5,QUERY!$C:$C,QUERY!AL:AL) -> 6000072 | GL5: =_xlfn.XLOOKUP(B5,QUERY!$C:$C,QUERY!AM:AM) -> Importación | GM5: =_xlfn.XLOOKUP(B5,QUERY!$C:$C,QUERY!AN:AN) -> CEFA SAFE (MEDICAMENTO DOSIFICADO DE USO VETERINARIO) | GN5: =_xlfn.XLOOKUP(B5,QUERY!$C:$C,QUERY!AO:AO) -> SIN CLASIFICACION | GO5: =_xlfn.XLOOKUP(B5,QUERY!$C:$C,QUERY!AP:AP) -> 0 | GP5: =_xlfn.XLOOKUP(B5,QUERY!$C:$C,QUERY!AQ:AQ) -> Cargas de Importación | GQ5: =_xlfn.XLOOKUP(B5,QUERY!$C:$C,QUERY!AR:AR) -> INTERVET MEXICO SA DE CV | GR5: =_xlfn.XLOOKUP(B5,QUERY!$C:$C,QUERY!AS:AS) -> 0 | GS5: =_xlfn.XLOOKUP(B5,QUERY!$C:$C,QUERY!AT:AT) -> NINGUNO | GT5: =_xlfn.XLOOKUP(B5,QUERY!$C:$C,QUERY!AU:AU) -> 0 | GU5: =_xlfn.XLOOKUP(B5,QUERY!$C:$C,QUERY!AV:AV) -> NINGUNO | GV5: =_xlfn.XLOOKUP(B5,QUERY!$C:$C,QUERY!AW:AW) -> PRODUCTO TERMINADO | GW5: =_xlfn.XLOOKUP(B5,QUERY!$C:$C,QUERY!AX:AX) -> Verde | GX5: =_xlfn.XLOOKUP(B5,QUERY!$C:$C,QUERY!AY:AY) -> SUPER EXPRESS DE CARGA FEDERAL S.A. DE C.V. | GY5: =_xlfn.XLOOKUP(B5,QUERY!$C:$C,QUERY!AZ:AZ) -> 0 | GZ5: =_xlfn.XLOOKUP(B5,QUERY!$C:$C,QUERY!BA:BA) -> IME-T006 | HA5: =_xlfn.XLOOKUP(B5,QUERY!$C:$C,QUERY!BB:BB) -> IME850329RH2 | HB5: =_xlfn.XLOOKUP(B5,QUERY!$C:$C,QUERY!BC:BC) -> 0 | HC5: =_xlfn.XLOOKUP(B5,QUERY!$C:$C,QUERY!BD:BD) -> 0.99 | HD5: =_xlfn.XLOOKUP(B5,QUERY!$C:$C,QUERY!BE:BE) -> LOTE: A217A05,LOTE: A219A02,LOTE: A219A01,LOTE: A217A04,LOTE: A217A03,LOTE: H107A01,LOTES: J550A01, J607A01,LOTE: 5677101 | HE5: =_xlfn.XLOOKUP(B5,QUERY!$C:$C,QUERY!BF:BF) -> 90 | HF5: =_xlfn.XLOOKUP(B5,QUERY!$C:$C,QUERY!BG:BG) -> 952448.23, 2181141.30, 863532.00 | HG5: =_xlfn.XLOOKUP(B5,QUERY!$C:$C,QUERY!BH:BH) -> KILO,KILO,KILO,KILO,KILO,KILO,KILO,KILO | HH5: =_xlfn.XLOOKUP(B5,QUERY!$C:$C,QUERY!BI:BI) -> 0 | HI5: =_xlfn.XLOOKUP(B5,QUERY!$C:$C,QUERY!BJ:BJ) -> ALEMANIA (REPUBLICA FEDERAL DE),PAISES BAJOS (REINO DE LOS) (HOLANDA) | HJ5: =_xlfn.XLOOKUP(B5,QUERY!$C:$C,QUERY!BK:BK) -> PAISES BAJOS (REINO DE LOS) (HOLANDA) | HK5: =_xlfn.XLOOKUP(B5,QUERY!$C:$C,QUERY!BL:BL) -> DEU,ZYA | HL5: =_xlfn.XLOOKUP(B5,QUERY!$C:$C,QUERY!BM:BM) -> ZYA | HM5: =_xlfn.XLOOKUP(B5,QUERY!$C:$C,QUERY!BN:BN) -> 3997122 | HN5: =_xlfn.XLOOKUP(B5,QUERY!$C:$C,QUERY!BO:BO) -> 462.00 | HO5: =_xlfn.XLOOKUP(B5,QUERY!$C:$C,QUERY!BP:BP) -> NULL | HP5: =_xlfn.XLOOKUP(B5,QUERY!$C:$C,QUERY!BQ:BQ) -> NULL | HQ5: =_xlfn.XLOOKUP(B5,QUERY!$C:$C,QUERY!BR:BR) -> 139939.61 | HR5: =_xlfn.XLOOKUP(B5,QUERY!$C:$C,QUERY!BS:BS) -> 0 | HS5: =_xlfn.XLOOKUP(B5,QUERY!$C:$C,QUERY!BT:BT) -> 0 | HT5: =_xlfn.XLOOKUP(B5,QUERY!$C:$C,QUERY!A:A) -> VERACRUZ | HU5: =_xlfn.XLOOKUP(B5,QUERY!$C:$C,QUERY!B:B) -> MARÍTIMO VERACRUZ
